Workbook

Sheet HuongDan
A1: FILE THỰC HÀNH: TÌM DỮ LIỆU, ĐI KHẢO SÁT VÀ KIỂM TRA ĐIỂM MỚI (ĐỀ TÀI NGÂN HÀNG X VÀ TRƯỜNG TIỂU HỌC Y)
A2: Đây là dữ liệu giả định dùng để học, không phải số liệu thật. Sheet 6 dùng lại đúng 165 phiếu thô của file 2.Chapter_2_and_Chapter_3_Practice.xlsx nên mọi con số khớp với sách (200 người được mời, 165 phiếu thu về, 15 phiếu bị loại, 150 phiếu hợp lệ).
A3: Dùng kèm sách "Hướng dẫn viết chuyên đề và khóa luận tốt nghiệp": Mục 2.1.3A, 3.4.1A, 3.5.1A, 3.5.1B và 3.5.1C (phần bổ sung thực hành). Các bảng trong sách đánh số BS1 đến BS13 để không làm thay đổi số bảng cũ.
A5: Thứ tự các sheet đi theo đúng thứ tự làm việc:
A6: 1_NhatKyTimTaiLieu: ghi mỗi lần tìm tài liệu (nguồn, chuỗi tìm kiếm, số kết quả, số bài giữ lại). Bảng BS1 của sách.
A7: 2_MaTranTaiLieu: ma trận 21 nghiên cứu (giả định) và bảng đếm khoảng trống bằng COUNTIFS. Bảng BS2 của sách.
A8: 3_SoCapThuCap: phân biệt dữ liệu sơ cấp và thứ cấp, chuỗi tư duy sáu bậc, nơi tìm dữ liệu thứ cấp. Bảng BS4 đến BS6.
A9: 4_KeHoachMau: từ cỡ mẫu tối thiểu đến số người cần mời; thử nhiều tình huống tỷ lệ phản hồi. Bảng BS8.
A10: 5_LichTiepXuc: lịch báo trước, gửi, nhắc lại và đóng khảo sát của Ngân hàng X. Bảng BS9.
A11: 6_DuLieuThoGanCo: 165 phiếu thô kèm các cột công thức gắn cờ: ngày, đợt trả lời, số ô trống, phiếu trùng, độ lệch chuẩn của dòng, kết luận giữ hay loại.
A12: 7_NhatKyThuThap: nhật ký từng ngày; số phiếu nhận và số phiếu lỗi được đếm tự động từ sheet 6. Bảng BS10.
A13: 8_SomMuon: kiểm tra sai lệch do không phản hồi bằng cách so sánh nhóm trả lời sớm và nhóm trả lời muộn (T.TEST). Bảng BS13.
... A20: Ô nền xám là tiêu đề. Ô nền vàng là ô sinh viên thay bằng số liệu của mình. Ô nền cam là kết quả cần đọc. Mọi ô số trong sheet 2, 4, 7, 8, 10, 11, 12 là công thức: bấm vào ô để xem công thức.

Sheet 1_NhatKyTimTaiLieu
A1: NHẬT KÝ TÌM TÀI LIỆU (ví dụ đề tài Ngân hàng X, số liệu giả định)
A2: Mỗi lần tìm là một dòng. Cột F là số bản ghi đã xem (Google Scholar trả về hàng nghìn kết quả nên chỉ xem 100 kết quả đầu theo mức liên quan). Cột G: số bài giữ lại sau khi đọc tên và tóm tắt. Cột H: số bài giữ lại sau khi đọc toàn văn, đã loại bài trùng với các dòng trên. Dừng lăn cầu tuyết khi một vòng không thêm bài mới (Wohlin, 2014).
A3: Vòng | B3: Ngày | C3: Nguồn | D3: Chuỗi tìm kiếm hoặc cách tìm | E3: Bộ lọc | F3: Số bản ghi đã xem | G3: Giữ sau tên và tóm tắt | H3: Giữ sau toàn văn | I3: Ghi chú
A4: 1 | B4: [ngày] | C4: Google Scholar | D4: ("mobile banking" OR "digital banking") AND (intention OR adoption) AND Vietnam | E4: Từ 2015 đến [năm]; 100 kết quả đầu | F4: 100 | G4: 19 | H4: 7 | I4: Ưu tiên bài trên tạp chí có bình duyệt
A5: 1 | B5: [ngày] | C5: ScienceDirect (qua thư viện) | D5: Như trên | E5: Research articles; từ 2015 | F5: 61 | G5: 12 | H5: 4 | I5: Loại 3 bài trùng với dòng 1
A6: 1 | B6: [ngày] | C6: Tạp chí khoa học trong nước | D6: "ngân hàng số" AND ("ý định" OR "chấp nhận") | E6: Từ 2018 | F6: 34 | G6: 8 | H6: 3 | I6: Đọc kỹ thang đo đã Việt hóa
A7: 2 | B7: [ngày] | C7: Lần ngược (backward) | D7: Danh mục tài liệu tham khảo của 5 bài chính | E7: Chỉ giữ bài đúng chủ đề | F7: 187 | G7: 11 | H7: 4 | I7: Tìm ra 2 bài gốc của thang đo niềm tin
A8: 2 | B8: [ngày] | C8: Lần xuôi (forward) | D8: Nút "Cited by" của 5 bài chính trên Google Scholar | E8: Từ 2020 | F8: 142 | G8: 9 | H8: 3 | I8: Tìm ra bài mới nhất về khách hàng ngoài thành phố lớn
A9: 3 | B9: [ngày] | C9: Lần ngược và lần xuôi | D9: Từ 7 bài mới của vòng 2 | E9: Như trên | F9: 96 | G9: 4 | H9: 0 | I9: Không thêm bài mới: dừng tìm
E10: Tổng | F10: =SUM(F4:F9) | G10: =SUM(G4:G9) | H10: =SUM(H4:H9)
A12: Câu viết vào khóa luận lấy số từ dòng Tổng: "Tác giả xem [F] bản ghi, giữ [G] bài sau khi đọc tên và tóm tắt và giữ [H] bài sau khi đọc toàn văn." Với số liệu trên: 620 bản ghi, 63 bài và 21 bài.

Sheet 2_MaTranTaiLieu
A1: MA TRẬN TÀI LIỆU VÀ BẢNG ĐẾM KHOẢNG TRỐNG (21 nghiên cứu giả định, không phải tài liệu thật)
A2: Mỗi hàng là một nghiên cứu đã giữ lại ở sheet 1. Cột E đến H: 1 = nghiên cứu có xét biến đó; 0 = không xét. Cột I: kết quả của sự dễ sử dụng (SD) nếu nghiên cứu có xét. Khi làm thật, cột A ghi tên tác giả và năm.
A3: Mã | B3: Bối cảnh | C3: Lý thuyết nền | D3: Đối tượng | E3: HI | F3: SD | G3: NT | H3: XH | I3: Kết quả SD | J3: Phương pháp | K3: Đơn vị khảo sát
A4: NC01 | B4: TP lớn | C4: TAM + UTAUT | D4: Sinh viên | E4: 1 | F4: 1 | G4: 1 | H4: 1 | I4: Có ý nghĩa | J4: PLS-SEM | K4: Ngân hàng khác
A5: NC02 | B5: TP lớn | C5: TAM | D5: Khách hàng cá nhân | E5: 1 | F5: 1 | G5: 1 | H5: 1 | I5: Không có ý nghĩa | J5: Hồi quy | K5: Ngân hàng khác
A6: NC03 | B6: TP lớn | C6: UTAUT | D6: Khách hàng cá nhân | E6: 1 | F6: 0 | G6: 1 | H6: 1 | J6: SEM | K6: Ngân hàng khác
A7: NC04 | B7: TP lớn | C7: TAM + TPB | D7: Khách hàng cá nhân | E7: 1 | F7: 1 | G7: 1 | H7: 1 | I7: Có ý nghĩa | J7: Hồi quy | K7: Ngân hàng khác
A8: NC05 | B8: TP lớn | C8: UTAUT | D8: Khách hàng cá nhân | E8: 1 | F8: 0 | G8: 1 | H8: 1 | J8: PLS-SEM | K8: Ngân hàng khác
A9: NC06 | B9: TP lớn | C9: UTAUT | D9: Sinh viên | E9: 1 | F9: 1 | G9: 1 | H9: 1 | I9: Không có ý nghĩa | J9: PLS-SEM | K9: Ngân hàng khác
A10: NC07 | B10: TP lớn | C10: TAM + TPB | D10: Khách hàng cá nhân | E10: 1 | F10: 0 | G10: 1 | H10: 1 | J10: SEM | K10: Ngân hàng khác
A11: NC08 | B11: Tỉnh | C11: TAM | D11: Khách hàng cá nhân | E11: 1 | F11: 1 | G11: 1 | H11: 1 | I11: Có ý nghĩa | J11: Hồi quy | K11: Ngân hàng khác
A12: NC09 | B12: TP lớn | C12: TAM | D12: Khách hàng cá nhân | E12: 1 | F12: 1 | G12: 0 | H12: 0 | I12: Có ý nghĩa | J12: Hồi quy | K12: Ngân hàng khác
A13: NC10 | B13: TP lớn | C13: TAM | D13: Khách hàng cá nhân | E13: 1 | F13: 1 | G13: 1 | H13: 0 | I13: Có ý nghĩa | J13: Hồi quy | K13: Ngân hàng khác
A14: NC11 | B14: TP lớn | C14: UTAUT | D14: Sinh viên | E14: 1 | F14: 1 | G14: 0 | H14: 1 | I14: Có ý nghĩa | J14: SEM | K14: Ngân hàng khác
A15: NC12 | B15: TP lớn | C15: TAM | D15: Khách hàng cá nhân | E15: 1 | F15: 1 | G15: 0 | H15: 0 | I15: Không có ý nghĩa | J15: PLS-SEM | K15: Ngân hàng khác
A16: NC13 | B16: TP lớn | C16: TAM | D16: Khách hàng cá nhân | E16: 1 | F16: 0 | G16: 1 | H16: 0 | J16: Hồi quy | K16: Ngân hàng khác
A17: NC14 | B17: TP lớn | C17: TPB | D17: Khách hàng cá nhân | E17: 0 | F17: 0 | G17: 1 | H17: 1 | J17: Hồi quy | K17: Ngân hàng khác
A18: NC15 | B18: TP lớn | C18: UTAUT | D18: Khách hàng cá nhân | E18: 1 | F18: 0 | G18: 0 | H18: 1 | J18: SEM | K18: Ngân hàng khác
A19: NC16 | B19: TP lớn | C19: TAM | D19: Sinh viên | E19: 1 | F19: 1 | G19: 0 | H19: 0 | I19: Có ý nghĩa | J19: Hồi quy | K19: Ngân hàng khác
A20: NC17 | B20: TP lớn | C20: Cam kết và niềm tin | D20: Khách hàng cá nhân | E20: 0 | F20: 0 | G20: 1 | H20: 0 | J20: SEM | K20: Ngân hàng khác
A21: NC18 | B21: Tỉnh | C21: TAM | D21: Khách hàng cá nhân | E21: 1 | F21: 1 | G21: 0 | H21: 0 | I21: Không có ý nghĩa | J21: Hồi quy | K21: Ngân hàng khác
A22: NC19 | B22: Tỉnh | C22: TAM | D22: Khách hàng cá nhân | E22: 1 | F22: 0 | G22: 1 | H22: 0 | J22: Hồi quy | K22: Ngân hàng khác
A23: NC20 | B23: Tỉnh | C23: TPB | D23: Khách hàng cá nhân | E23: 0 | F23: 0 | G23: 0 | H23: 1 | J23: Hồi quy | K23: Ngân hàng khác
A24: NC21 | B24: TP lớn | C24: TAM | D24: Sinh viên | E24: 1 | F24: 0 | G24: 1 | H24: 0 | J24: PLS-SEM | K24: Ngân hàng khác
A26: BẢNG ĐẾM KHOẢNG TRỐNG (Bảng BS2 của sách)
A27: Câu hỏi đếm | B27: Kết quả | C27: Cách đọc
A28: Tổng số nghiên cứu trong ma trận | B28: =COUNTA($A$4:$A$24) | C28: Quy mô tổng quan; nên từ 15 đến 20 trở lên
A29: Xét đồng thời HI, NT và XH | B29: =COUNTIFS($E$4:$E$24,1,$G$4:$G$24,1,$H$4:$H$24,1) | C29: Lớn hơn 0: tổ hợp biến không mới
A30: ... trong đó khảo sát ngoài thành phố lớn | B30: =COUNTIFS($E$4:$E$24,1,$G$4:$G$24,1,$H$4:$H$24,1,$B$4:$B$24,"Tỉnh") | C30: Rất ít: khoảng trống loại 1 (bối cảnh)
A31: Khảo sát tại Ngân hàng X | B31: =COUNTIF($K$4:$K$24,"Ngân hàng X") | C31: Bằng 0 nhưng yếu nếu đứng một mình (Whetten, 1989)
A32: SD có ý nghĩa | B32: =COUNTIF($I$4:$I$24,"Có ý nghĩa") | C32: So với dòng dưới
A33: SD không có ý nghĩa | B33: =COUNTIF($I$4:$I$24,"Không có ý nghĩa") | C33: Hai dòng đều lớn hơn 0: khoảng trống loại 4 (kết quả trái chiều)
A34: Tỷ lệ nghiên cứu ở thành phố lớn (%) | B34: =COUNTIF($B$4:$B$24,"TP lớn")/COUNTA($A$4:$A$24)*100 | C34: Căn cứ cho câu "chủ yếu khảo sát tại các thành phố lớn"
A36: Ô bằng 0 chỉ là ứng viên khoảng trống. Sinh viên phải giải thích vì sao bối cảnh đó có thể làm kết quả khác đi; nếu không, "chưa ai nghiên cứu ở đơn vị của em" chưa phải điểm mới.

Sheet 3_SoCapThuCap
A1: DỮ LIỆU SƠ CẤP VÀ DỮ LIỆU THỨ CẤP
A2: Bảng BS4. So sánh hai loại dữ liệu
A3: Tiêu chí | B3: Dữ liệu sơ cấp | C3: Dữ liệu thứ cấp
A4: Ai thu thập | B4: Chính sinh viên | C4: Cơ quan, tổ chức hoặc nhà nghiên cứu khác
A5: Thu để làm gì | B5: Trả lời đúng câu hỏi nghiên cứu của đề tài | C5: Mục đích riêng của người thu; đề tài dùng lại
A6: Ví dụ Ngân hàng X | B6: 165 phiếu Google Form của khách hàng cá nhân | C6: Báo cáo thường niên của Ngân hàng X; niên giám thống kê; số liệu của ngân hàng trung ương
A7: Ví dụ Trường Tiểu học Y | B7: 131 phiếu giấy của phụ huynh; biên bản 10 buổi phỏng vấn | C7: Kế hoạch năm học, báo cáo tổng kết của trường (khi được Ban giám hiệu cho phép)
A8: Ưu điểm | B8: Đo đúng biến cần đo; biết rõ cách thu | C8: Có sẵn, nhanh, nhiều năm, ít tốn kém
A9: Hạn chế | B9: Mất 2 đến 3 tuần; phụ thuộc người trả lời; dễ sai lệch nếu thu sai cách | C9: Định nghĩa và cách đo có thể khác khái niệm của đề tài; có thể đã cũ
A10: Vai trò trong khóa luận khảo sát | B10: Kiểm định giả thuyết H1 đến H4 | C10: Mô tả bối cảnh ở Chương 1; giải thích kết quả ở Chương 4
A11: Phải ghi lại | B11: Quy trình thu ở mục 3.5.1: thời gian, kênh, số mời, số thu, số loại | C11: Tên tổ chức, năm, tên tài liệu, trang hoặc bảng, ngày truy cập
A13: Bảng BS5. Chuỗi tư duy sáu bậc: từ câu hỏi nghiên cứu đến người cầm phiếu
A14: Bậc | B14: Ngân hàng X | C14: Trường Tiểu học Y
A15: 1. Câu hỏi cần con số hay câu chuyện? | B15: Con số: mức tác động của bốn yếu tố đến ý định sử dụng | C15: Con số: mức tác động của ba yếu tố đến sự hài lòng; câu chuyện: phụ huynh trải nghiệm thủ tục ra sao
A16: 2. Con số đo khái niệm nào? | B16: HI, SD, NT, XH, YD (19 câu hỏi) | C16: CSVC, TDNV, QTHC, HL (16 câu hỏi)
A17: 3. Ai biết câu trả lời? | B17: Khách hàng cá nhân đã đăng ký ngân hàng số; không hỏi nhân viên ngân hàng | C17: Phụ huynh đã làm thủ tục trong năm học; không hỏi học sinh
A18: 4. Dữ liệu đã có sẵn chưa? | B18: Chưa: ý định và niềm tin không có trong báo cáo nào. Thu sơ cấp | C18: Chưa: sự hài lòng về thủ tục không có trong báo cáo của trường. Thu sơ cấp
A19: 5. Thu bằng gì, gặp ở đâu, qua ai, lúc nào? | B19: Google Form; tại quầy (mã QR) và qua email, Zalo; xin phép Giám đốc phòng giao dịch | C19: Phiếu giấy tại cổng trường giờ đón con; xin phép Ban giám hiệu
A20: 6. Không gặp được thì làm gì? | B20: Thêm phòng giao dịch thứ hai; kéo dài thêm một tuần; ghi vào hạn chế | C20: Gửi phiếu qua giáo viên chủ nhiệm; thêm buổi họp phụ huynh
A22: Bảng BS6. Nơi tìm dữ liệu thứ cấp và điều cần ghi lại
A23: Loại dữ liệu | B23: Nguồn gốc nên lấy | C23: Lưu ý
A24: Số liệu dân số, kinh tế, doanh nghiệp | B24: Niên giám thống kê của cơ quan thống kê quốc gia (trang nso.gov.vn, trước đây gso.gov.vn) | C24: Ghi năm xuất bản, tên bảng; không lấy số qua bài báo kể lại
A25: Số liệu ngành ngân hàng | B25: Trang thông tin của Ngân hàng Nhà nước; báo cáo của hiệp hội ngành | C25: Ghi rõ chỉ tiêu được định nghĩa thế nào
A26: Số liệu của một ngân hàng | B26: Báo cáo thường niên, báo cáo tài chính trên trang quan hệ nhà đầu tư | C26: Ghi năm và số trang; lưu bản PDF
A27: Số liệu của trường học | B27: Kế hoạch năm học, báo cáo tổng kết, báo cáo tự đánh giá | C27: Chỉ dùng khi được phép; không đưa thông tin cá nhân
A28: Tài liệu tổ chức, công khai, mạng xã hội | B28: Fanpage, Zalo OA, bình luận công khai (Trần Phước, n.d., tr. 49) | C28: Chụp màn hình có ngày; ẩn tên người bình luận
A29: Nghiên cứu trước | B29: Bài báo, luận văn tìm qua sheet 1 | C29: Là tài liệu tham khảo cho Chương 2, không phải dữ liệu để kiểm định
A31: Năm câu hỏi đánh giá một nguồn thứ cấp trước khi dùng
A32: Câu hỏi | B32: Ví dụ trả lời đạt | C32: Nếu trả lời không
A33: Ai thu và có uy tín không? | B33: Cơ quan thống kê quốc gia | C33: Tìm nguồn gốc của con số
A34: Thu để làm gì? | B34: Thống kê chính thức hằng năm | C34: Cân nhắc sai lệch do mục đích quảng bá
A35: Thu khi nào? | B35: Năm gần nhất có số liệu | C35: Ghi rõ năm; giải thích vì sao dùng số cũ
A36: Định nghĩa có khớp khái niệm của đề tài không? | B36: "Tài khoản thanh toán cá nhân" khớp phạm vi khách hàng cá nhân | C36: Không dùng làm bằng chứng trực tiếp
A37: Dẫn nguồn đầy đủ được không? | B37: Có tên, năm, trang, đường dẫn | C37: Không dùng

Sheet 4_KeHoachMau
A1: TỪ CỠ MẪU TỐI THIỂU ĐẾN SỐ NGƯỜI CẦN MỜI (Bảng BS8 của sách)
A2: Sinh viên chỉ sửa các ô nền vàng. Công thức: số cần mời = số phiếu hợp lệ mục tiêu chia cho (tỷ lệ phản hồi dự kiến nhân tỷ lệ phiếu hợp lệ dự kiến), làm tròn lên.
A3: Chỉ tiêu | B3: Giá trị | C3: Ghi chú
A4: Số biến quan sát (câu hỏi đo khái niệm) | B4: 19 | C4: Bảng 13 của sách
A5: Số biến độc lập | B5: 4 | C5: HI, SD, NT, XH
A6: Tối thiểu theo Hair và cộng sự (2010): 5 nhân số câu | B6: =5*B4 | C6: Cho phân tích nhân tố
A7: Tối thiểu theo Green (1991): 50 + 8m | B7: =50+8*B5 | C7: Cho hồi quy
A8: Cỡ mẫu tối thiểu | B8: =MAX(B6,B7) | C8: Lấy số lớn hơn
A9: Số phiếu hợp lệ mục tiêu | B9: 150 | C9: Bảng 12 của sách
A10: Tỷ lệ phản hồi dự kiến | B10: 0.8 | C10: Ước lượng khi lập kế hoạch
A11: Tỷ lệ phiếu hợp lệ dự kiến | B11: 0.94 | C11: Ước lượng khi lập kế hoạch
A12: SỐ NGƯỜI CẦN MỜI | B12: =ROUNDUP(B9/(B10*B11),0) | C12: Ngân hàng X đã mời 200 người
A14: Thử các tình huống (cùng mục tiêu 150 phiếu hợp lệ)
A15: Tình huống | B15: Tỷ lệ phản hồi | C15: Tỷ lệ hợp lệ | D15: Số cần mời
A16: Ngân hàng X thực tế: mời tại quầy và trực tuyến | B16: 0.825 | C16: 0.90909091 | D16: =ROUNDUP(150/(B16*C16),0)
A17: Chỉ gửi trực tuyến, tỷ lệ bằng mức trung bình 52,7% của Baruch và Holtom (2008) | B17: 0.527 | C17: 0.9 | D17: =ROUNDUP(150/(B17*C17),0)
A18: Chỉ đăng một lần lên mạng xã hội, không nhắc lại (giả định) | B18: 0.3 | C18: 0.85 | D18: =ROUNDUP(150/(B18*C18),0)
A20: Cách đọc: cùng mục tiêu 150 phiếu, khảo sát chỉ qua mạng ở mức phản hồi trung bình cần mời khoảng 317 người, gấp hơn một lần rưỡi Ngân hàng X. Vì vậy kế hoạch mời phải làm trước khi phát phiếu, không làm sau khi thấy thiếu.

Sheet 5_LichTiepXuc
A1: LỊCH TIẾP XÚC CỦA NGÂN HÀNG X (Bảng BS9 của sách)
A2: Dillman và cộng sự (2014) xem khảo sát là một chuỗi tiếp xúc có kế hoạch. Mốc ngày khớp với dấu thời gian của 165 phiếu ở sheet 6. Các ngày nhắc lại cũng là ranh giới chia nhóm trả lời sớm và muộn ở sheet 8.
A3: Ngày | B3: Thứ | C3: Việc | D3: Nội dung chính
A4: 45712 | B4: Thứ Hai | C4: Xin phép | D4: Nộp giấy giới thiệu của Khoa; Giám đốc phòng giao dịch đồng ý cho đặt mã QR tại quầy từ 8 giờ đến 10 giờ
A5: 45714 | B5: Thứ Tư | C5: Thử phiếu | D5: Đọc thử với 5 khách hàng; khảo sát thử 30 người để tính Alpha sơ bộ (không gộp vào dữ liệu chính thức)
A6: 45719 | B6: Thứ Hai | C6: Gửi đợt 1 | D6: Gửi 50 email cá nhân hóa; bắt đầu mời tại quầy
A7: 45720 | B7: Thứ Ba | C7: Gửi đợt 2 | D7: Gửi tin nhắn Zalo cho 40 khách hàng đã đồng ý nhận tin
A8: 45721 | B8: Thứ Tư | C8: Gửi đợt 3 | D8: Gửi tin nhắn Zalo cho 30 khách hàng còn lại
A9: 45722 | B9: Thứ Năm | C9: Nhắc lần 1 | D9: Nhắn chung: cảm ơn người đã trả lời, mời người chưa trả lời; ghi ngày nhắc
A10: 45729 | B10: Thứ Năm | C10: Nhắc lần 2 | D10: Nhắn lần cuối, nói rõ ngày đóng khảo sát
A11: 45733 | B11: Thứ Hai | C11: Đóng | D11: Tắt "Chấp nhận phản hồi"; tải file thô; gửi lời cảm ơn phòng giao dịch

Sheet 6_DuLieuThoGanCo
A1: Dấu thời gian | B1: GT | C1: TUOI | D1: THUNHAP | E1: TGSD | F1: HI1 | G1: HI2 | H1: HI3 | I1: HI4 | J1: SD1 | K1: SD2 | L1: SD3 | M1: SD4 | N1: NT1 | O1: NT2 | P1: NT3 | Q1: NT4 | R1: XH1 | S1: XH2 | T1: XH3 | U1: XH4 | V1: YD1 | W1: YD2 | X1: YD3 | Y1: Ngày | Z1: Đợt | AA1: Số ô trống | AB1: Khóa so trùng | AC1: Trùng | AD1: Độ lệch chuẩn dòng | AE1: Giữ | AF1: Lý do loại | AG1: HI | AH1: SD | AI1: NT | AJ1: XH | AK1: YD
A2: 45719.569 | B2: 2 | C2: 2 | D2: 2 | E2: 2 | F2: 5 | G2: 4 | H2: 5 | I2: 5 | J2: 5 | K2: 5 | L2: 5 | M2: 5 | N2: 2 | O2: 3 | P2: 2 | Q2: 4 | R2: 5 | S2: 4 | T2: 4 | U2: 4 | V2: 4 | W2: 5 | X2: 4 | Y2: =INT(A2) | Z2: =IF(Y2<DATE(2025,3,6),1,IF(Y2<DATE(2025,3,13),2,3)) | AA2: =COUNTBLANK(B2:X2) | AB2: =B2&"|"&C2&"|"&D2&"|"&E2&"|"&F2&"|"&G2&"|"&H2&"|"&I2&"|"&J2&"|"&K2&"|"&L2&"|"&M2&"|"&N2&"|"&O2&"|"&P2&"|"&Q2&"|"&R2&"|"&S2&"|"&T2&"|"&U2&"|"&V2&"|"&W2&"|"&X2 | AC2: =IF(COUNTIF($AB$2:AB2,AB2)>1,1,0) | AD2: =STDEV(F2:X2) | AE2: =IF(OR(AA2>=8,AC2=1,AD2=0),0,1) | AF2: =IF(AE2=1,"",IF(AC2=1,"Trùng",IF(AA2>=8,"Bỏ trống "&AA2&" ô","Chọn cùng một mức"))) | AG2: =IF($AE2=1,AVERAGE(F2:I2),"") | AH2: =IF($AE2=1,AVERAGE(J2:M2),"") | AI2: =IF($AE2=1,AVERAGE(N2:Q2),"") | AJ2: =IF($AE2=1,AVERAGE(R2:U2),"") | AK2: =IF($AE2=1,AVERAGE(V2:X2),"")
A3: 45719.637 | B3: 1 | C3: 2 | D3: 3 | E3: 3 | F3: 3 | G3: 2 | H3: 3 | I3: 3 | J3: 3 | K3: 3 | L3: 2 | M3: 2 | N3: 3 | O3: 3 | P3: 4 | Q3: 5 | R3: 2 | S3: 3 | T3: 3 | U3: 1 | V3: 3 | W3: 2 | X3: 1 | Y3: =INT(A3) | Z3: =IF(Y3<DATE(2025,3,6),1,IF(Y3<DATE(2025,3,13),2,3)) | AA3: =COUNTBLANK(B3:X3) | AB3: =B3&"|"&C3&"|"&D3&"|"&E3&"|"&F3&"|"&G3&"|"&H3&"|"&I3&"|"&J3&"|"&K3&"|"&L3&"|"&M3&"|"&N3&"|"&O3&"|"&P3&"|"&Q3&"|"&R3&"|"&S3&"|"&T3&"|"&U3&"|"&V3&"|"&W3&"|"&X3 | AC3: =IF(COUNTIF($AB$2:AB3,AB3)>1,1,0) | AD3: =STDEV(F3:X3) | AE3: =IF(OR(AA3>=8,AC3=1,AD3=0),0,1) | AF3: =IF(AE3=1,"",IF(AC3=1,"Trùng",IF(AA3>=8,"Bỏ trống "&AA3&" ô","Chọn cùng một mức"))) | AG3: =IF($AE3=1,AVERAGE(F3:I3),"") | AH3: =IF($AE3=1,AVERAGE(J3:M3),"") | AI3: =IF($AE3=1,AVERAGE(N3:Q3),"") | AJ3: =IF($AE3=1,AVERAGE(R3:U3),"") | AK3: =IF($AE3=1,AVERAGE(V3:X3),"")
A4: 45719.691 | B4: 1 | C4: 1 | D4: 3 | E4: 2 | F4: 3 | G4: 3 | H4: 2 | I4: 3 | J4: 4 | K4: 5 | L4: 4 | M4: 3 | N4: 4 | O4: 4 | P4: 4 | Q4: 4 | R4: 2 | S4: 5 | T4: 4 | U4: 4 | V4: 4 | W4: 3 | X4: 4 | Y4: =INT(A4) | Z4: =IF(Y4<DATE(2025,3,6),1,IF(Y4<DATE(2025,3,13),2,3)) | AA4: =COUNTBLANK(B4:X4) | AB4: =B4&"|"&C4&"|"&D4&"|"&E4&"|"&F4&"|"&G4&"|"&H4&"|"&I4&"|"&J4&"|"&K4&"|"&L4&"|"&M4&"|"&N4&"|"&O4&"|"&P4&"|"&Q4&"|"&R4&"|"&S4&"|"&T4&"|"&U4&"|"&V4&"|"&W4&"|"&X4 | AC4: =IF(COUNTIF($AB$2:AB4,AB4)>1,1,0) | AD4: =STDEV(F4:X4) | AE4: =IF(OR(AA4>=8,AC4=1,AD4=0),0,1) | AF4: =IF(AE4=1,"",IF(AC4=1,"Trùng",IF(AA4>=8,"Bỏ trống "&AA4&" ô","Chọn cùng một mức"))) | AG4: =IF($AE4=1,AVERAGE(F4:I4),"") | AH4: =IF($AE4=1,AVERAGE(J4:M4),"") | AI4: =IF($AE4=1,AVERAGE(N4:Q4),"") | AJ4: =IF($AE4=1,AVERAGE(R4:U4),"") | AK4: =IF($AE4=1,AVERAGE(V4:X4),"")
A5: 45719.708 | B5: 2 | C5: 2 | D5: 2 | E5: 2 | F5: 4 | G5: 3 | H5: 2 | I5: 2 | J5: 3 | K5: 3 | L5: 3 | M5: 3 | N5: 3 | O5: 2 | P5: 2 | Q5: 3 | R5: 2 | S5: 3 | T5: 3 | U5: 1 | V5: 3 | W5: 1 | X5: 3 | Y5: =INT(A5) | Z5: =IF(Y5<DATE(2025,3,6),1,IF(Y5<DATE(2025,3,13),2,3)) | AA5: =COUNTBLANK(B5:X5) | AB5: =B5&"|"&C5&"|"&D5&"|"&E5&"|"&F5&"|"&G5&"|"&H5&"|"&I5&"|"&J5&"|"&K5&"|"&L5&"|"&M5&"|"&N5&"|"&O5&"|"&P5&"|"&Q5&"|"&R5&"|"&S5&"|"&T5&"|"&U5&"|"&V5&"|"&W5&"|"&X5 | AC5: =IF(COUNTIF($AB$2:AB5,AB5)>1,1,0) | AD5: =STDEV(F5:X5) | AE5: =IF(OR(AA5>=8,AC5=1,AD5=0),0,1) | AF5: =IF(AE5=1,"",IF(AC5=1,"Trùng",IF(AA5>=8,"Bỏ trống "&AA5&" ô","Chọn cùng một mức"))) | AG5: =IF($AE5=1,AVERAGE(F5:I5),"") | AH5: =IF($AE5=1,AVERAGE(J5:M5),"") | AI5: =IF($AE5=1,AVERAGE(N5:Q5),"") | AJ5: =IF($AE5=1,AVERAGE(R5:U5),"") | AK5: =IF($AE5=1,AVERAGE(V5:X5),"")
A6: 45719.826 | B6: 2 | C6: 4 | D6: 3 | E6: 2 | F6: 3 | G6: 4 | H6: 3 | I6: 4 | J6: 4 | K6: 4 | L6: 5 | M6: 5 | N6: 4 | O6: 3 | P6: 3 | Q6: 3 | R6: 5 | S6: 3 | T6: 4 | U6: 4 | V6: 4 | W6: 5 | X6: 5 | Y6: =INT(A6) | Z6: =IF(Y6<DATE(2025,3,6),1,IF(Y6<DATE(2025,3,13),2,3)) | AA6: =COUNTBLANK(B6:X6) | AB6: =B6&"|"&C6&"|"&D6&"|"&E6&"|"&F6&"|"&G6&"|"&H6&"|"&I6&"|"&J6&"|"&K6&"|"&L6&"|"&M6&"|"&N6&"|"&O6&"|"&P6&"|"&Q6&"|"&R6&"|"&S6&"|"&T6&"|"&U6&"|"&V6&"|"&W6&"|"&X6 | AC6: =IF(COUNTIF($AB$2:AB6,AB6)>1,1,0) | AD6: =STDEV(F6:X6) | AE6: =IF(OR(AA6>=8,AC6=1,AD6=0),0,1) | AF6: =IF(AE6=1,"",IF(AC6=1,"Trùng",IF(AA6>=8,"Bỏ trống "&AA6&" ô","Chọn cùng một mức"))) | AG6: =IF($AE6=1,AVERAGE(F6:I6),"") | AH6: =IF($AE6=1,AVERAGE(J6:M6),"") | AI6: =IF($AE6=1,AVERAGE(N6:Q6),"") | AJ6: =IF($AE6=1,AVERAGE(R6:U6),"") | AK6: =IF($AE6=1,AVERAGE(V6:X6),"")
A7: 45720.096 | B7: 1 | C7: 3 | D7: 3 | E7: 2 | F7: 4 | G7: 4 | H7: 5 | I7: 3 | J7: 4 | K7: 4 | L7: 4 | M7: 4 | N7: 5 | O7: 5 | P7: 5 | Q7: 4 | R7: 4 | S7: 2 | T7: 4 | U7: 4 | V7: 4 | W7: 3 | X7: 4 | Y7: =INT(A7) | Z7: =IF(Y7<DATE(2025,3,6),1,IF(Y7<DATE(2025,3,13),2,3)) | AA7: =COUNTBLANK(B7:X7) | AB7: =B7&"|"&C7&"|"&D7&"|"&E7&"|"&F7&"|"&G7&"|"&H7&"|"&I7&"|"&J7&"|"&K7&"|"&L7&"|"&M7&"|"&N7&"|"&O7&"|"&P7&"|"&Q7&"|"&R7&"|"&S7&"|"&T7&"|"&U7&"|"&V7&"|"&W7&"|"&X7 | AC7: =IF(COUNTIF($AB$2:AB7,AB7)>1,1,0) | AD7: =STDEV(F7:X7) | AE7: =IF(OR(AA7>=8,AC7=1,AD7=0),0,1) | AF7: =IF(AE7=1,"",IF(AC7=1,"Trùng",IF(AA7>=8,"Bỏ trống "&AA7&" ô","Chọn cùng một mức"))) | AG7: =IF($AE7=1,AVERAGE(F7:I7),"") | AH7: =IF($AE7=1,AVERAGE(J7:M7),"") | AI7: =IF($AE7=1,AVERAGE(N7:Q7),"") | AJ7: =IF($AE7=1,AVERAGE(R7:U7),"") | AK7: =IF($AE7=1,AVERAGE(V7:X7),"")
A8: 45720.114 | B8: 1 | C8: 3 | D8: 1 | E8: 2 | F8: 3 | G8: 4 | H8: 4 | I8: 3 | J8: 4 | K8: 3 | L8: 3 | M8: 3 | N8: 4 | O8: 4 | P8: 3 | Q8: 3 | R8: 5 | S8: 5 | T8: 4 | U8: 4 | V8: 3 | W8: 3 | X8: 4 | Y8: =INT(A8) | Z8: =IF(Y8<DATE(2025,3,6),1,IF(Y8<DATE(2025,3,13),2,3)) | AA8: =COUNTBLANK(B8:X8) | AB8: =B8&"|"&C8&"|"&D8&"|"&E8&"|"&F8&"|"&G8&"|"&H8&"|"&I8&"|"&J8&"|"&K8&"|"&L8&"|"&M8&"|"&N8&"|"&O8&"|"&P8&"|"&Q8&"|"&R8&"|"&S8&"|"&T8&"|"&U8&"|"&V8&"|"&W8&"|"&X8 | AC8: =IF(COUNTIF($AB$2:AB8,AB8)>1,1,0) | AD8: =STDEV(F8:X8) | AE8: =IF(OR(AA8>=8,AC8=1,AD8=0),0,1) | AF8: =IF(AE8=1,"",IF(AC8=1,"Trùng",IF(AA8>=8,"Bỏ trống "&AA8&" ô","Chọn cùng một mức"))) | AG8: =IF($AE8=1,AVERAGE(F8:I8),"") | AH8: =IF($AE8=1,AVERAGE(J8:M8),"") | AI8: =IF($AE8=1,AVERAGE(N8:Q8),"") | AJ8: =IF($AE8=1,AVERAGE(R8:U8),"") | AK8: =IF($AE8=1,AVERAGE(V8:X8),"")
A9: 45720.183 | B9: 1 | C9: 2 | D9: 2 | E9: 1 | F9: 4 | G9: 3 | H9: 4 | I9: 5 | J9: 4 | K9: 4 | L9: 4 | M9: 5 | N9: 4 | O9: 4 | P9: 4 | Q9: 4 | R9: 2 | S9: 3 | T9: 4 | U9: 3 | V9: 3 | W9: 3 | X9: 3 | Y9: =INT(A9) | Z9: =IF(Y9<DATE(2025,3,6),1,IF(Y9<DATE(2025,3,13),2,3)) | AA9: =COUNTBLANK(B9:X9) | AB9: =B9&"|"&C9&"|"&D9&"|"&E9&"|"&F9&"|"&G9&"|"&H9&"|"&I9&"|"&J9&"|"&K9&"|"&L9&"|"&M9&"|"&N9&"|"&O9&"|"&P9&"|"&Q9&"|"&R9&"|"&S9&"|"&T9&"|"&U9&"|"&V9&"|"&W9&"|"&X9 | AC9: =IF(COUNTIF($AB$2:AB9,AB9)>1,1,0) | AD9: =STDEV(F9:X9) | AE9: =IF(OR(AA9>=8,AC9=1,AD9=0),0,1) | AF9: =IF(AE9=1,"",IF(AC9=1,"Trùng",IF(AA9>=8,"Bỏ trống "&AA9&" ô","Chọn cùng một mức"))) | AG9: =IF($AE9=1,AVERAGE(F9:I9),"") | AH9: =IF($AE9=1,AVERAGE(J9:M9),"") | AI9: =IF($AE9=1,AVERAGE(N9:Q9),"") | AJ9: =IF($AE9=1,AVERAGE(R9:U9),"") | AK9: =IF($AE9=1,AVERAGE(V9:X9),"")
A10: 45720.184 | B10: 1 | C10: 2 | D10: 2 | E10: 1 | F10: 4 | G10: 3 | H10: 4 | I10: 5 | J10: 4 | K10: 4 | L10: 4 | M10: 5 | N10: 4 | O10: 4 | P10: 4 | Q10: 4 | R10: 2 | S10: 3 | T10: 4 | U10: 3 | V10: 3 | W10: 3 | X10: 3 | Y10: =INT(A10) | Z10: =IF(Y10<DATE(2025,3,6),1,IF(Y10<DATE(2025,3,13),2,3)) | AA10: =COUNTBLANK(B10:X10) | AB10: =B10&"|"&C10&"|"&D10&"|"&E10&"|"&F10&"|"&G10&"|"&H10&"|"&I10&"|"&J10&"|"&K10&"|"&L10&"|"&M10&"|"&N10&"|"&O10&"|"&P10&"|"&Q10&"|"&R10&"|"&S10&"|"&T10&"|"&U10&"|"&V10&"|"&W10&"|"&X10 | AC10: =IF(COUNTIF($AB$2:AB10,AB10)>1,1,0) | AD10: =STDEV(F10:X10) | AE10: =IF(OR(AA10>=8,AC10=1,AD10=0),0,1) | AF10: =IF(AE10=1,"",IF(AC10=1,"Trùng",IF(AA10>=8,"Bỏ trống "&AA10&" ô","Chọn cùng một mức"))) | AG10: =IF($AE10=1,AVERAGE(F10:I10),"") | AH10: =IF($AE10=1,AVERAGE(J10:M10),"") | AI10: =IF($AE10=1,AVERAGE(N10:Q10),"") | AJ10: =IF($AE10=1,AVERAGE(R10:U10),"") | AK10: =IF($AE10=1,AVERAGE(V10:X10),"")
A11: 45720.196 | B11: 1 | C11: 4 | D11: 1 | E11: 2 | F11: 4 | G11: 5 | H11: 4 | I11: 4 | J11: 3 | K11: 3 | L11: 4 | M11: 5 | N11: 3 | O11: 4 | P11: 3 | Q11: 3 | R11: 2 | S11: 2 | T11: 2 | U11: 2 | V11: 3 | W11: 2 | X11: 2 | Y11: =INT(A11) | Z11: =IF(Y11<DATE(2025,3,6),1,IF(Y11<DATE(2025,3,13),2,3)) | AA11: =COUNTBLANK(B11:X11) | AB11: =B11&"|"&C11&"|"&D11&"|"&E11&"|"&F11&"|"&G11&"|"&H11&"|"&I11&"|"&J11&"|"&K11&"|"&L11&"|"&M11&"|"&N11&"|"&O11&"|"&P11&"|"&Q11&"|"&R11&"|"&S11&"|"&T11&"|"&U11&"|"&V11&"|"&W11&"|"&X11 | AC11: =IF(COUNTIF($AB$2:AB11,AB11)>1,1,0) | AD11: =STDEV(F11:X11) | AE11: =IF(OR(AA11>=8,AC11=1,AD11=0),0,1) | AF11: =IF(AE11=1,"",IF(AC11=1,"Trùng",IF(AA11>=8,"Bỏ trống "&AA11&" ô","Chọn cùng một mức"))) | AG11: =IF($AE11=1,AVERAGE(F11:I11),"") | AH11: =IF($AE11=1,AVERAGE(J11:M11),"") | AI11: =IF($AE11=1,AVERAGE(N11:Q11),"") | AJ11: =IF($AE11=1,AVERAGE(R11:U11),"") | AK11: =IF($AE11=1,AVERAGE(V11:X11),"")
A12: 45720.239 | B12: 1 | C12: 3 | D12: 2 | E12: 3 | F12: 5 | G12: 5 | H12: 4 | I12: 5 | J12: 5 | K12: 5 | L12: 5 | M12: 5 | N12: 3 | O12: 3 | P12: 4 | Q12: 3 | R12: 4 | S12: 3 | T12: 5 | U12: 5 | V12: 4 | W12: 4 | X12: 4 | Y12: =INT(A12) | Z12: =IF(Y12<DATE(2025,3,6),1,IF(Y12<DATE(2025,3,13),2,3)) | AA12: =COUNTBLANK(B12:X12) | AB12: =B12&"|"&C12&"|"&D12&"|"&E12&"|"&F12&"|"&G12&"|"&H12&"|"&I12&"|"&J12&"|"&K12&"|"&L12&"|"&M12&"|"&N12&"|"&O12&"|"&P12&"|"&Q12&"|"&R12&"|"&S12&"|"&T12&"|"&U12&"|"&V12&"|"&W12&"|"&X12 | AC12: =IF(COUNTIF($AB$2:AB12,AB12)>1,1,0) | AD12: =STDEV(F12:X12) | AE12: =IF(OR(AA12>=8,AC12=1,AD12=0),0,1) | AF12: =IF(AE12=1,"",IF(AC12=1,"Trùng",IF(AA12>=8,"Bỏ trống "&AA12&" ô","Chọn cùng một mức"))) | AG12: =IF($AE12=1,AVERAGE(F12:I12),"") | AH12: =IF($AE12=1,AVERAGE(J12:M12),"") | AI12: =IF($AE12=1,AVERAGE(N12:Q12),"") | AJ12: =IF($AE12=1,AVERAGE(R12:U12),"") | AK12: =IF($AE12=1,AVERAGE(V12:X12),"")
A13: 45720.452 | B13: 2 | C13: 2 | D13: 2 | E13: 2 | F13: 5 | G13: 5 | H13: 4 | I13: 4 | J13: 5 | K13: 5 | L13: 4 | M13: 5 | N13: 3 | O13: 3 | P13: 3 | Q13: 3 | R13: 4 | S13: 4 | T13: 3 | U13: 4 | V13: 4 | W13: 4 | X13: 4 | Y13: =INT(A13) | Z13: =IF(Y13<DATE(2025,3,6),1,IF(Y13<DATE(2025,3,13),2,3)) | AA13: =COUNTBLANK(B13:X13) | AB13: =B13&"|"&C13&"|"&D13&"|"&E13&"|"&F13&"|"&G13&"|"&H13&"|"&I13&"|"&J13&"|"&K13&"|"&L13&"|"&M13&"|"&N13&"|"&O13&"|"&P13&"|"&Q13&"|"&R13&"|"&S13&"|"&T13&"|"&U13&"|"&V13&"|"&W13&"|"&X13 | AC13: =IF(COUNTIF($AB$2:AB13,AB13)>1,1,0) | AD13: =STDEV(F13:X13) | AE13: =IF(OR(AA13>=8,AC13=1,AD13=0),0,1) | AF13: =IF(AE13=1,"",IF(AC13=1,"Trùng",IF(AA13>=8,"Bỏ trống "&AA13&" ô","Chọn cùng một mức"))) | AG13: =IF($AE13=1,AVERAGE(F13:I13),"") | AH13: =IF($AE13=1,AVERAGE(J13:M13),"") | AI13: =IF($AE13=1,AVERAGE(N13:Q13),"") | AJ13: =IF($AE13=1,AVERAGE(R13:U13),"") | AK13: =IF($AE13=1,AVERAGE(V13:X13),"")
A14: 45720.562 | B14: 2 | C14: 4 | D14: 2 | E14: 1 | F14: 5 | G14: 5 | H14: 4 | I14: 5 | J14: 5 | K14: 5 | L14: 5 | M14: 5 | N14: 4 | O14: 4 | P14: 4 | Q14: 3 | R14: 4 | S14: 5 | T14: 4 | U14: 4 | V14: 4 | W14: 5 | X14: 4 | Y14: =INT(A14) | Z14: =IF(Y14<DATE(2025,3,6),1,IF(Y14<DATE(2025,3,13),2,3)) | AA14: =COUNTBLANK(B14:X14) | AB14: =B14&"|"&C14&"|"&D14&"|"&E14&"|"&F14&"|"&G14&"|"&H14&"|"&I14&"|"&J14&"|"&K14&"|"&L14&"|"&M14&"|"&N14&"|"&O14&"|"&P14&"|"&Q14&"|"&R14&"|"&S14&"|"&T14&"|"&U14&"|"&V14&"|"&W14&"|"&X14 | AC14: =IF(COUNTIF($AB$2:AB14,AB14)>1,1,0) | AD14: =STDEV(F14:X14) | AE14: =IF(OR(AA14>=8,AC14=1,AD14=0),0,1) | AF14: =IF(AE14=1,"",IF(AC14=1,"Trùng",IF(AA14>=8,"Bỏ trống "&AA14&" ô","Chọn cùng một mức"))) | AG14: =IF($AE14=1,AVERAGE(F14:I14),"") | AH14: =IF($AE14=1,AVERAGE(J14:M14),"") | AI14: =IF($AE14=1,AVERAGE(N14:Q14),"") | AJ14: =IF($AE14=1,AVERAGE(R14:U14),"") | AK14: =IF($AE14=1,AVERAGE(V14:X14),"")
A15: 45720.702 | B15: 3 | C15: 5 | D15: 5 | E15: 4 | G15: 4 | H15: 3 | J15: 3 | K15: 3 | M15: 3 | N15: 5 | S15: 1 | U15: 1 | V15: 2 | X15: 5 | Y15: =INT(A15) | Z15: =IF(Y15<DATE(2025,3,6),1,IF(Y15<DATE(2025,3,13),2,3)) | AA15: =COUNTBLANK(B15:X15) | AB15: =B15&"|"&C15&"|"&D15&"|"&E15&"|"&F15&"|"&G15&"|"&H15&"|"&I15&"|"&J15&"|"&K15&"|"&L15&"|"&M15&"|"&N15&"|"&O15&"|"&P15&"|"&Q15&"|"&R15&"|"&S15&"|"&T15&"|"&U15&"|"&V15&"|"&W15&"|"&X15 | AC15: =IF(COUNTIF($AB$2:AB15,AB15)>1,1,0) | AD15: =STDEV(F15:X15) | AE15: =IF(OR(AA15>=8,AC15=1,AD15=0),0,1) | AF15: =IF(AE15=1,"",IF(AC15=1,"Trùng",IF(AA15>=8,"Bỏ trống "&AA15&" ô","Chọn cùng một mức"))) | AG15: =IF($AE15=1,AVERAGE(F15:I15),"") | AH15: =IF($AE15=1,AVERAGE(J15:M15),"") | AI15: =IF($AE15=1,AVERAGE(N15:Q15),"") | AJ15: =IF($AE15=1,AVERAGE(R15:U15),"") | AK15: =IF($AE15=1,AVERAGE(V15:X15),"")
A16: 45720.728 | B16: 1 | C16: 1 | D16: 1 | E16: 2 | F16: 5 | G16: 5 | H16: 4 | I16: 5 | J16: 5 | K16: 4 | L16: 3 | M16: 4 | N16: 4 | O16: 4 | P16: 5 | Q16: 5 | R16: 5 | S16: 5 | T16: 5 | U16: 5 | V16: 5 | W16: 5 | X16: 4 | Y16: =INT(A16) | Z16: =IF(Y16<DATE(2025,3,6),1,IF(Y16<DATE(2025,3,13),2,3)) | AA16: =COUNTBLANK(B16:X16) | AB16: =B16&"|"&C16&"|"&D16&"|"&E16&"|"&F16&"|"&G16&"|"&H16&"|"&I16&"|"&J16&"|"&K16&"|"&L16&"|"&M16&"|"&N16&"|"&O16&"|"&P16&"|"&Q16&"|"&R16&"|"&S16&"|"&T16&"|"&U16&"|"&V16&"|"&W16&"|"&X16 | AC16: =IF(COUNTIF($AB$2:AB16,AB16)>1,1,0) | AD16: =STDEV(F16:X16) | AE16: =IF(OR(AA16>=8,AC16=1,AD16=0),0,1) | AF16: =IF(AE16=1,"",IF(AC16=1,"Trùng",IF(AA16>=8,"Bỏ trống "&AA16&" ô","Chọn cùng một mức"))) | AG16: =IF($AE16=1,AVERAGE(F16:I16),"") | AH16: =IF($AE16=1,AVERAGE(J16:M16),"") | AI16: =IF($AE16=1,AVERAGE(N16:Q16),"") | AJ16: =IF($AE16=1,AVERAGE(R16:U16),"") | AK16: =IF($AE16=1,AVERAGE(V16:X16),"")
A17: 45720.838 | B17: 2 | C17: 1 | D17: 2 | E17: 2 | F17: 3 | G17: 3 | H17: 3 | I17: 3 | J17: 3 | K17: 3 | L17: 3 | M17: 3 | N17: 3 | O17: 4 | P17: 3 | Q17: 5 | R17: 4 | S17: 4 | T17: 4 | U17: 3 | V17: 3 | W17: 4 | X17: 2 | Y17: =INT(A17) | Z17: =IF(Y17<DATE(2025,3,6),1,IF(Y17<DATE(2025,3,13),2,3)) | AA17: =COUNTBLANK(B17:X17) | AB17: =B17&"|"&C17&"|"&D17&"|"&E17&"|"&F17&"|"&G17&"|"&H17&"|"&I17&"|"&J17&"|"&K17&"|"&L17&"|"&M17&"|"&N17&"|"&O17&"|"&P17&"|"&Q17&"|"&R17&"|"&S17&"|"&T17&"|"&U17&"|"&V17&"|"&W17&"|"&X17 | AC17: =IF(COUNTIF($AB$2:AB17,AB17)>1,1,0) | AD17: =STDEV(F17:X17) | AE17: =IF(OR(AA17>=8,AC17=1,AD17=0),0,1) | AF17: =IF(AE17=1,"",IF(AC17=1,"Trùng",IF(AA17>=8,"Bỏ trống "&AA17&" ô","Chọn cùng một mức"))) | AG17: =IF($AE17=1,AVERAGE(F17:I17),"") | AH17: =IF($AE17=1,AVERAGE(J17:M17),"") | AI17: =IF($AE17=1,AVERAGE(N17:Q17),"") | AJ17: =IF($AE17=1,AVERAGE(R17:U17),"") | AK17: =IF($AE17=1,AVERAGE(V17:X17),"")
A18: 45720.856 | B18: 1 | C18: 4 | D18: 2 | E18: 3 | F18: 5 | G18: 4 | H18: 3 | I18: 4 | J18: 3 | K18: 4 | L18: 4 | M18: 3 | N18: 5 | O18: 4 | P18: 5 | Q18: 4 | R18: 5 | S18: 3 | T18: 5 | U18: 4 | V18: 5 | W18: 5 | X18: 4 | Y18: =INT(A18) | Z18: =IF(Y18<DATE(2025,3,6),1,IF(Y18<DATE(2025,3,13),2,3)) | AA18: =COUNTBLANK(B18:X18) | AB18: =B18&"|"&C18&"|"&D18&"|"&E18&"|"&F18&"|"&G18&"|"&H18&"|"&I18&"|"&J18&"|"&K18&"|"&L18&"|"&M18&"|"&N18&"|"&O18&"|"&P18&"|"&Q18&"|"&R18&"|"&S18&"|"&T18&"|"&U18&"|"&V18&"|"&W18&"|"&X18 | AC18: =IF(COUNTIF($AB$2:AB18,AB18)>1,1,0) | AD18: =STDEV(F18:X18) | AE18: =IF(OR(AA18>=8,AC18=1,AD18=0),0,1) | AF18: =IF(AE18=1,"",IF(AC18=1,"Trùng",IF(AA18>=8,"Bỏ trống "&AA18&" ô","Chọn cùng một mức"))) | AG18: =IF($AE18=1,AVERAGE(F18:I18),"") | AH18: =IF($AE18=1,AVERAGE(J18:M18),"") | AI18: =IF($AE18=1,AVERAGE(N18:Q18),"") | AJ18: =IF($AE18=1,AVERAGE(R18:U18),"") | AK18: =IF($AE18=1,AVERAGE(V18:X18),"")
A19: 45721.029 | B19: 2 | C19: 1 | D19: 2 | E19: 2 | F19: 5 | G19: 5 | H19: 5 | I19: 5 | J19: 3 | K19: 4 | L19: 4 | M19: 4 | N19: 4 | O19: 4 | P19: 5 | Q19: 5 | R19: 5 | S19: 4 | T19: 5 | U19: 4 | V19: 5 | W19: 5 | X19: 4 | Y19: =INT(A19) | Z19: =IF(Y19<DATE(2025,3,6),1,IF(Y19<DATE(2025,3,13),2,3)) | AA19: =COUNTBLANK(B19:X19) | AB19: =B19&"|"&C19&"|"&D19&"|"&E19&"|"&F19&"|"&G19&"|"&H19&"|"&I19&"|"&J19&"|"&K19&"|"&L19&"|"&M19&"|"&N19&"|"&O19&"|"&P19&"|"&Q19&"|"&R19&"|"&S19&"|"&T19&"|"&U19&"|"&V19&"|"&W19&"|"&X19 | AC19: =IF(COUNTIF($AB$2:AB19,AB19)>1,1,0) | AD19: =STDEV(F19:X19) | AE19: =IF(OR(AA19>=8,AC19=1,AD19=0),0,1) | AF19: =IF(AE19=1,"",IF(AC19=1,"Trùng",IF(AA19>=8,"Bỏ trống "&AA19&" ô","Chọn cùng một mức"))) | AG19: =IF($AE19=1,AVERAGE(F19:I19),"") | AH19: =IF($AE19=1,AVERAGE(J19:M19),"") | AI19: =IF($AE19=1,AVERAGE(N19:Q19),"") | AJ19: =IF($AE19=1,AVERAGE(R19:U19),"") | AK19: =IF($AE19=1,AVERAGE(V19:X19),"")
A20: 45721.031 | B20: 2 | C20: 1 | D20: 2 | E20: 1 | F20: 3 | G20: 3 | H20: 3 | I20: 5 | J20: 5 | K20: 5 | L20: 4 | M20: 3 | N20: 4 | O20: 3 | P20: 3 | Q20: 4 | R20: 3 | S20: 1 | T20: 3 | U20: 2 | V20: 3 | W20: 4 | X20: 5 | Y20: =INT(A20) | Z20: =IF(Y20<DATE(2025,3,6),1,IF(Y20<DATE(2025,3,13),2,3)) | AA20: =COUNTBLANK(B20:X20) | AB20: =B20&"|"&C20&"|"&D20&"|"&E20&"|"&F20&"|"&G20&"|"&H20&"|"&I20&"|"&J20&"|"&K20&"|"&L20&"|"&M20&"|"&N20&"|"&O20&"|"&P20&"|"&Q20&"|"&R20&"|"&S20&"|"&T20&"|"&U20&"|"&V20&"|"&W20&"|"&X20 | AC20: =IF(COUNTIF($AB$2:AB20,AB20)>1,1,0) | AD20: =STDEV(F20:X20) | AE20: =IF(OR(AA20>=8,AC20=1,AD20=0),0,1) | AF20: =IF(AE20=1,"",IF(AC20=1,"Trùng",IF(AA20>=8,"Bỏ trống "&AA20&" ô","Chọn cùng một mức"))) | AG20: =IF($AE20=1,AVERAGE(F20:I20),"") | AH20: =IF($AE20=1,AVERAGE(J20:M20),"") | AI20: =IF($AE20=1,AVERAGE(N20:Q20),"") | AJ20: =IF($AE20=1,AVERAGE(R20:U20),"") | AK20: =IF($AE20=1,AVERAGE(V20:X20),"")
A21: 45721.126 | B21: 2 | C21: 2 | D21: 2 | E21: 3 | F21: 3 | G21: 2 | H21: 3 | I21: 3 | J21: 4 | K21: 2 | L21: 3 | M21: 3 | N21: 3 | O21: 3 | P21: 2 | Q21: 3 | R21: 3 | S21: 3 | T21: 2 | U21: 3 | V21: 3 | W21: 3 | X21: 2 | Y21: =INT(A21) | Z21: =IF(Y21<DATE(2025,3,6),1,IF(Y21<DATE(2025,3,13),2,3)) | AA21: =COUNTBLANK(B21:X21) | AB21: =B21&"|"&C21&"|"&D21&"|"&E21&"|"&F21&"|"&G21&"|"&H21&"|"&I21&"|"&J21&"|"&K21&"|"&L21&"|"&M21&"|"&N21&"|"&O21&"|"&P21&"|"&Q21&"|"&R21&"|"&S21&"|"&T21&"|"&U21&"|"&V21&"|"&W21&"|"&X21 | AC21: =IF(COUNTIF($AB$2:AB21,AB21)>1,1,0) | AD21: =STDEV(F21:X21) | AE21: =IF(OR(AA21>=8,AC21=1,AD21=0),0,1) | AF21: =IF(AE21=1,"",IF(AC21=1,"Trùng",IF(AA21>=8,"Bỏ trống "&AA21&" ô","Chọn cùng một mức"))) | AG21: =IF($AE21=1,AVERAGE(F21:I21),"") | AH21: =IF($AE21=1,AVERAGE(J21:M21),"") | AI21: =IF($AE21=1,AVERAGE(N21:Q21),"") | AJ21: =IF($AE21=1,AVERAGE(R21:U21),"") | AK21: =IF($AE21=1,AVERAGE(V21:X21),"")
A22: 45721.385 | B22: 2 | C22: 3 | D22: 1 | E22: 2 | F22: 3 | G22: 3 | H22: 4 | I22: 4 | J22: 3 | K22: 3 | L22: 3 | M22: 3 | N22: 4 | O22: 4 | P22: 4 | Q22: 4 | R22: 4 | S22: 3 | T22: 3 | U22: 4 | V22: 4 | W22: 3 | X22: 3 | Y22: =INT(A22) | Z22: =IF(Y22<DATE(2025,3,6),1,IF(Y22<DATE(2025,3,13),2,3)) | AA22: =COUNTBLANK(B22:X22) | AB22: =B22&"|"&C22&"|"&D22&"|"&E22&"|"&F22&"|"&G22&"|"&H22&"|"&I22&"|"&J22&"|"&K22&"|"&L22&"|"&M22&"|"&N22&"|"&O22&"|"&P22&"|"&Q22&"|"&R22&"|"&S22&"|"&T22&"|"&U22&"|"&V22&"|"&W22&"|"&X22 | AC22: =IF(COUNTIF($AB$2:AB22,AB22)>1,1,0) | AD22: =STDEV(F22:X22) | AE22: =IF(OR(AA22>=8,AC22=1,AD22=0),0,1) | AF22: =IF(AE22=1,"",IF(AC22=1,"Trùng",IF(AA22>=8,"Bỏ trống "&AA22&" ô","Chọn cùng một mức"))) | AG22: =IF($AE22=1,AVERAGE(F22:I22),"") | AH22: =IF($AE22=1,AVERAGE(J22:M22),"") | AI22: =IF($AE22=1,AVERAGE(N22:Q22),"") | AJ22: =IF($AE22=1,AVERAGE(R22:U22),"") | AK22: =IF($AE22=1,AVERAGE(V22:X22),"")
A23: 45721.469 | B23: 1 | C23: 2 | D23: 2 | E23: 2 | F23: 5 | G23: 4 | H23: 4 | I23: 4 | J23: 4 | K23: 4 | L23: 4 | M23: 3 | N23: 3 | O23: 4 | P23: 3 | Q23: 3 | R23: 3 | S23: 4 | T23: 4 | U23: 3 | V23: 4 | W23: 5 | X23: 4 | Y23: =INT(A23) | Z23: =IF(Y23<DATE(2025,3,6),1,IF(Y23<DATE(2025,3,13),2,3)) | AA23: =COUNTBLANK(B23:X23) | AB23: =B23&"|"&C23&"|"&D23&"|"&E23&"|"&F23&"|"&G23&"|"&H23&"|"&I23&"|"&J23&"|"&K23&"|"&L23&"|"&M23&"|"&N23&"|"&O23&"|"&P23&"|"&Q23&"|"&R23&"|"&S23&"|"&T23&"|"&U23&"|"&V23&"|"&W23&"|"&X23 | AC23: =IF(COUNTIF($AB$2:AB23,AB23)>1,1,0) | AD23: =STDEV(F23:X23) | AE23: =IF(OR(AA23>=8,AC23=1,AD23=0),0,1) | AF23: =IF(AE23=1,"",IF(AC23=1,"Trùng",IF(AA23>=8,"Bỏ trống "&AA23&" ô","Chọn cùng một mức"))) | AG23: =IF($AE23=1,AVERAGE(F23:I23),"") | AH23: =IF($AE23=1,AVERAGE(J23:M23),"") | AI23: =IF($AE23=1,AVERAGE(N23:Q23),"") | AJ23: =IF($AE23=1,AVERAGE(R23:U23),"") | AK23: =IF($AE23=1,AVERAGE(V23:X23),"")
A24: 45721.482 | B24: 1 | C24: 2 | D24: 3 | E24: 1 | F24: 3 | G24: 3 | H24: 3 | I24: 3 | J24: 4 | K24: 4 | L24: 4 | M24: 3 | N24: 4 | O24: 5 | P24: 2 | Q24: 4 | R24: 4 | S24: 4 | T24: 4 | U24: 4 | V24: 4 | W24: 4 | X24: 5 | Y24: =INT(A24) | Z24: =IF(Y24<DATE(2025,3,6),1,IF(Y24<DATE(2025,3,13),2,3)) | AA24: =COUNTBLANK(B24:X24) | AB24: =B24&"|"&C24&"|"&D24&"|"&E24&"|"&F24&"|"&G24&"|"&H24&"|"&I24&"|"&J24&"|"&K24&"|"&L24&"|"&M24&"|"&N24&"|"&O24&"|"&P24&"|"&Q24&"|"&R24&"|"&S24&"|"&T24&"|"&U24&"|"&V24&"|"&W24&"|"&X24 | AC24: =IF(COUNTIF($AB$2:AB24,AB24)>1,1,0) | AD24: =STDEV(F24:X24) | AE24: =IF(OR(AA24>=8,AC24=1,AD24=0),0,1) | AF24: =IF(AE24=1,"",IF(AC24=1,"Trùng",IF(AA24>=8,"Bỏ trống "&AA24&" ô","Chọn cùng một mức"))) | AG24: =IF($AE24=1,AVERAGE(F24:I24),"") | AH24: =IF($AE24=1,AVERAGE(J24:M24),"") | AI24: =IF($AE24=1,AVERAGE(N24:Q24),"") | AJ24: =IF($AE24=1,AVERAGE(R24:U24),"") | AK24: =IF($AE24=1,AVERAGE(V24:X24),"")
A25: 45721.487 | B25: 1 | C25: 3 | D25: 1 | E25: 1 | F25: 5 | G25: 5 | H25: 4 | I25: 5 | J25: 4 | K25: 5 | L25: 4 | M25: 4 | N25: 5 | O25: 3 | P25: 4 | Q25: 5 | R25: 3 | S25: 3 | T25: 3 | U25: 4 | V25: 4 | W25: 5 | X25: 5 | Y25: =INT(A25) | Z25: =IF(Y25<DATE(2025,3,6),1,IF(Y25<DATE(2025,3,13),2,3)) | AA25: =COUNTBLANK(B25:X25) | AB25: =B25&"|"&C25&"|"&D25&"|"&E25&"|"&F25&"|"&G25&"|"&H25&"|"&I25&"|"&J25&"|"&K25&"|"&L25&"|"&M25&"|"&N25&"|"&O25&"|"&P25&"|"&Q25&"|"&R25&"|"&S25&"|"&T25&"|"&U25&"|"&V25&"|"&W25&"|"&X25 | AC25: =IF(COUNTIF($AB$2:AB25,AB25)>1,1,0) | AD25: =STDEV(F25:X25) | AE25: =IF(OR(AA25>=8,AC25=1,AD25=0),0,1) | AF25: =IF(AE25=1,"",IF(AC25=1,"Trùng",IF(AA25>=8,"Bỏ trống "&AA25&" ô","Chọn cùng một mức"))) | AG25: =IF($AE25=1,AVERAGE(F25:I25),"") | AH25: =IF($AE25=1,AVERAGE(J25:M25),"") | AI25: =IF($AE25=1,AVERAGE(N25:Q25),"") | AJ25: =IF($AE25=1,AVERAGE(R25:U25),"") | AK25: =IF($AE25=1,AVERAGE(V25:X25),"")
A26: 45721.567 | B26: 1 | C26: 3 | D26: 1 | E26: 2 | F26: 4 | G26: 4 | H26: 4 | I26: 3 | J26: 2 | K26: 3 | L26: 4 | M26: 4 | N26: 3 | O26: 4 | P26: 4 | Q26: 4 | R26: 4 | S26: 5 | T26: 4 | U26: 4 | V26: 4 | W26: 5 | X26: 4 | Y26: =INT(A26) | Z26: =IF(Y26<DATE(2025,3,6),1,IF(Y26<DATE(2025,3,13),2,3)) | AA26: =COUNTBLANK(B26:X26) | AB26: =B26&"|"&C26&"|"&D26&"|"&E26&"|"&F26&"|"&G26&"|"&H26&"|"&I26&"|"&J26&"|"&K26&"|"&L26&"|"&M26&"|"&N26&"|"&O26&"|"&P26&"|"&Q26&"|"&R26&"|"&S26&"|"&T26&"|"&U26&"|"&V26&"|"&W26&"|"&X26 | AC26: =IF(COUNTIF($AB$2:AB26,AB26)>1,1,0) | AD26: =STDEV(F26:X26) | AE26: =IF(OR(AA26>=8,AC26=1,AD26=0),0,1) | AF26: =IF(AE26=1,"",IF(AC26=1,"Trùng",IF(AA26>=8,"Bỏ trống "&AA26&" ô","Chọn cùng một mức"))) | AG26: =IF($AE26=1,AVERAGE(F26:I26),"") | AH26: =IF($AE26=1,AVERAGE(J26:M26),"") | AI26: =IF($AE26=1,AVERAGE(N26:Q26),"") | AJ26: =IF($AE26=1,AVERAGE(R26:U26),"") | AK26: =IF($AE26=1,AVERAGE(V26:X26),"")
A27: 45721.597 | B27: 2 | C27: 1 | D27: 1 | E27: 1 | F27: 5 | G27: 5 | H27: 5 | I27: 5 | J27: 5 | K27: 4 | L27: 5 | M27: 5 | N27: 4 | O27: 4 | P27: 3 | Q27: 3 | R27: 2 | S27: 4 | T27: 4 | U27: 4 | V27: 5 | W27: 5 | X27: 5 | Y27: =INT(A27) | Z27: =IF(Y27<DATE(2025,3,6),1,IF(Y27<DATE(2025,3,13),2,3)) | AA27: =COUNTBLANK(B27:X27) | AB27: =B27&"|"&C27&"|"&D27&"|"&E27&"|"&F27&"|"&G27&"|"&H27&"|"&I27&"|"&J27&"|"&K27&"|"&L27&"|"&M27&"|"&N27&"|"&O27&"|"&P27&"|"&Q27&"|"&R27&"|"&S27&"|"&T27&"|"&U27&"|"&V27&"|"&W27&"|"&X27 | AC27: =IF(COUNTIF($AB$2:AB27,AB27)>1,1,0) | AD27: =STDEV(F27:X27) | AE27: =IF(OR(AA27>=8,AC27=1,AD27=0),0,1) | AF27: =IF(AE27=1,"",IF(AC27=1,"Trùng",IF(AA27>=8,"Bỏ trống "&AA27&" ô","Chọn cùng một mức"))) | AG27: =IF($AE27=1,AVERAGE(F27:I27),"") | AH27: =IF($AE27=1,AVERAGE(J27:M27),"") | AI27: =IF($AE27=1,AVERAGE(N27:Q27),"") | AJ27: =IF($AE27=1,AVERAGE(R27:U27),"") | AK27: =IF($AE27=1,AVERAGE(V27:X27),"")
... A29: 45721.755 | B29: 1 | C29: 2 | D29: 1 | E29: 1 | F29: 4 | G29: 3 | H29: 3 | I29: 4 | J29: 4 | K29: 3 | L29: 3 | M29: 3 | N29: 4 | O29: 4 | P29: 4 | Q29: 4 | R29: 4 | S29: 3 | T29: 4 | U29: 3 | V29: 5 | W29: 4 | X29: 4 | Y29: =INT(A29) | Z29: =IF(Y29<DATE(2025,3,6),1,IF(Y29<DATE(2025,3,13),2,3)) | AA29: =COUNTBLANK(B29:X29) | AB29: =B29&"|"&C29&"|"&D29&"|"&E29&"|"&F29&"|"&G29&"|"&H29&"|"&I29&"|"&J29&"|"&K29&"|"&L29&"|"&M29&"|"&N29&"|"&O29&"|"&P29&"|"&Q29&"|"&R29&"|"&S29&"|"&T29&"|"&U29&"|"&V29&"|"&W29&"|"&X29 | AC29: =IF(COUNTIF($AB$2:AB29,AB29)>1,1,0) | AD29: =STDEV(F29:X29) | AE29: =IF(OR(AA29>=8,AC29=1,AD29=0),0,1) | AF29: =IF(AE29=1,"",IF(AC29=1,"Trùng",IF(AA29>=8,"Bỏ trống "&AA29&" ô","Chọn cùng một mức"))) | AG29: =IF($AE29=1,AVERAGE(F29:I29),"") | AH29: =IF($AE29=1,AVERAGE(J29:M29),"") | AI29: =IF($AE29=1,AVERAGE(N29:Q29),"") | AJ29: =IF($AE29=1,AVERAGE(R29:U29),"") | AK29: =IF($AE29=1,AVERAGE(V29:X29),"")
A30: 45721.757 | B30: 1 | C30: 5 | D30: 1 | E30: 5 | G30: 5 | H30: 2 | K30: 4 | M30: 1 | P30: 3 | R30: 4 | S30: 4 | T30: 2 | V30: 2 | X30: 5 | Y30: =INT(A30) | Z30: =IF(Y30<DATE(2025,3,6),1,IF(Y30<DATE(2025,3,13),2,3)) | AA30: =COUNTBLANK(B30:X30) | AB30: =B30&"|"&C30&"|"&D30&"|"&E30&"|"&F30&"|"&G30&"|"&H30&"|"&I30&"|"&J30&"|"&K30&"|"&L30&"|"&M30&"|"&N30&"|"&O30&"|"&P30&"|"&Q30&"|"&R30&"|"&S30&"|"&T30&"|"&U30&"|"&V30&"|"&W30&"|"&X30 | AC30: =IF(COUNTIF($AB$2:AB30,AB30)>1,1,0) | AD30: =STDEV(F30:X30) | AE30: =IF(OR(AA30>=8,AC30=1,AD30=0),0,1) | AF30: =IF(AE30=1,"",IF(AC30=1,"Trùng",IF(AA30>=8,"Bỏ trống "&AA30&" ô","Chọn cùng một mức"))) | AG30: =IF($AE30=1,AVERAGE(F30:I30),"") | AH30: =IF($AE30=1,AVERAGE(J30:M30),"") | AI30: =IF($AE30=1,AVERAGE(N30:Q30),"") | AJ30: =IF($AE30=1,AVERAGE(R30:U30),"") | AK30: =IF($AE30=1,AVERAGE(V30:X30),"")
A31: 45721.89 | B31: 1 | C31: 5 | D31: 3 | E31: 1 | I31: 5 | K31: 4 | N31: 2 | Q31: 2 | Y31: =INT(A31) | Z31: =IF(Y31<DATE(2025,3,6),1,IF(Y31<DATE(2025,3,13),2,3)) | AA31: =COUNTBLANK(B31:X31) | AB31: =B31&"|"&C31&"|"&D31&"|"&E31&"|"&F31&"|"&G31&"|"&H31&"|"&I31&"|"&J31&"|"&K31&"|"&L31&"|"&M31&"|"&N31&"|"&O31&"|"&P31&"|"&Q31&"|"&R31&"|"&S31&"|"&T31&"|"&U31&"|"&V31&"|"&W31&"|"&X31 | AC31: =IF(COUNTIF($AB$2:AB31,AB31)>1,1,0) | AD31: =STDEV(F31:X31) | AE31: =IF(OR(AA31>=8,AC31=1,AD31=0),0,1) | AF31: =IF(AE31=1,"",IF(AC31=1,"Trùng",IF(AA31>=8,"Bỏ trống "&AA31&" ô","Chọn cùng một mức"))) | AG31: =IF($AE31=1,AVERAGE(F31:I31),"") | AH31: =IF($AE31=1,AVERAGE(J31:M31),"") | AI31: =IF($AE31=1,AVERAGE(N31:Q31),"") | AJ31: =IF($AE31=1,AVERAGE(R31:U31),"") | AK31: =IF($AE31=1,AVERAGE(V31:X31),"")
A32: 45722.01 | B32: 2 | C32: 4 | D32: 1 | E32: 3 | F32: 4 | G32: 5 | H32: 4 | I32: 4 | J32: 4 | K32: 4 | L32: 3 | M32: 4 | N32: 3 | O32: 2 | P32: 3 | Q32: 2 | R32: 4 | S32: 4 | T32: 3 | U32: 2 | V32: 3 | W32: 3 | X32: 2 | Y32: =INT(A32) | Z32: =IF(Y32<DATE(2025,3,6),1,IF(Y32<DATE(2025,3,13),2,3)) | AA32: =COUNTBLANK(B32:X32) | AB32: =B32&"|"&C32&"|"&D32&"|"&E32&"|"&F32&"|"&G32&"|"&H32&"|"&I32&"|"&J32&"|"&K32&"|"&L32&"|"&M32&"|"&N32&"|"&O32&"|"&P32&"|"&Q32&"|"&R32&"|"&S32&"|"&T32&"|"&U32&"|"&V32&"|"&W32&"|"&X32 | AC32: =IF(COUNTIF($AB$2:AB32,AB32)>1,1,0) | AD32: =STDEV(F32:X32) | AE32: =IF(OR(AA32>=8,AC32=1,AD32=0),0,1) | AF32: =IF(AE32=1,"",IF(AC32=1,"Trùng",IF(AA32>=8,"Bỏ trống "&AA32&" ô","Chọn cùng một mức"))) | AG32: =IF($AE32=1,AVERAGE(F32:I32),"") | AH32: =IF($AE32=1,AVERAGE(J32:M32),"") | AI32: =IF($AE32=1,AVERAGE(N32:Q32),"") | AJ32: =IF($AE32=1,AVERAGE(R32:U32),"") | AK32: =IF($AE32=1,AVERAGE(V32:X32),"")
A33: 45722.092 | B33: 1 | C33: 2 | D33: 3 | E33: 3 | F33: 4 | G33: 4 | H33: 3 | I33: 4 | J33: 2 | K33: 3 | L33: 1 | M33: 3 | N33: 3 | O33: 4 | P33: 4 | Q33: 4 | R33: 3 | S33: 3 | T33: 4 | U33: 3 | V33: 3 | W33: 3 | X33: 4 | Y33: =INT(A33) | Z33: =IF(Y33<DATE(2025,3,6),1,IF(Y33<DATE(2025,3,13),2,3)) | AA33: =COUNTBLANK(B33:X33) | AB33: =B33&"|"&C33&"|"&D33&"|"&E33&"|"&F33&"|"&G33&"|"&H33&"|"&I33&"|"&J33&"|"&K33&"|"&L33&"|"&M33&"|"&N33&"|"&O33&"|"&P33&"|"&Q33&"|"&R33&"|"&S33&"|"&T33&"|"&U33&"|"&V33&"|"&W33&"|"&X33 | AC33: =IF(COUNTIF($AB$2:AB33,AB33)>1,1,0) | AD33: =STDEV(F33:X33) | AE33: =IF(OR(AA33>=8,AC33=1,AD33=0),0,1) | AF33: =IF(AE33=1,"",IF(AC33=1,"Trùng",IF(AA33>=8,"Bỏ trống "&AA33&" ô","Chọn cùng một mức"))) | AG33: =IF($AE33=1,AVERAGE(F33:I33),"") | AH33: =IF($AE33=1,AVERAGE(J33:M33),"") | AI33: =IF($AE33=1,AVERAGE(N33:Q33),"") | AJ33: =IF($AE33=1,AVERAGE(R33:U33),"") | AK33: =IF($AE33=1,AVERAGE(V33:X33),"")
A34: 45722.122 | B34: 1 | C34: 2 | D34: 3 | E34: 2 | F34: 3 | G34: 4 | H34: 2 | I34: 3 | J34: 4 | K34: 4 | L34: 2 | M34: 3 | N34: 4 | O34: 2 | P34: 4 | Q34: 2 | R34: 2 | S34: 2 | T34: 2 | U34: 3 | V34: 3 | W34: 3 | X34: 2 | Y34: =INT(A34) | Z34: =IF(Y34<DATE(2025,3,6),1,IF(Y34<DATE(2025,3,13),2,3)) | AA34: =COUNTBLANK(B34:X34) | AB34: =B34&"|"&C34&"|"&D34&"|"&E34&"|"&F34&"|"&G34&"|"&H34&"|"&I34&"|"&J34&"|"&K34&"|"&L34&"|"&M34&"|"&N34&"|"&O34&"|"&P34&"|"&Q34&"|"&R34&"|"&S34&"|"&T34&"|"&U34&"|"&V34&"|"&W34&"|"&X34 | AC34: =IF(COUNTIF($AB$2:AB34,AB34)>1,1,0) | AD34: =STDEV(F34:X34) | AE34: =IF(OR(AA34>=8,AC34=1,AD34=0),0,1) | AF34: =IF(AE34=1,"",IF(AC34=1,"Trùng",IF(AA34>=8,"Bỏ trống "&AA34&" ô","Chọn cùng một mức"))) | AG34: =IF($AE34=1,AVERAGE(F34:I34),"") | AH34: =IF($AE34=1,AVERAGE(J34:M34),"") | AI34: =IF($AE34=1,AVERAGE(N34:Q34),"") | AJ34: =IF($AE34=1,AVERAGE(R34:U34),"") | AK34: =IF($AE34=1,AVERAGE(V34:X34),"")
A35: 45722.168 | B35: 1 | C35: 1 | D35: 1 | E35: 2 | F35: 4 | G35: 4 | H35: 4 | I35: 4 | J35: 4 | K35: 4 | L35: 2 | M35: 4 | N35: 2 | O35: 3 | P35: 3 | Q35: 1 | R35: 3 | S35: 4 | T35: 3 | U35: 4 | V35: 5 | W35: 5 | X35: 4 | Y35: =INT(A35) | Z35: =IF(Y35<DATE(2025,3,6),1,IF(Y35<DATE(2025,3,13),2,3)) | AA35: =COUNTBLANK(B35:X35) | AB35: =B35&"|"&C35&"|"&D35&"|"&E35&"|"&F35&"|"&G35&"|"&H35&"|"&I35&"|"&J35&"|"&K35&"|"&L35&"|"&M35&"|"&N35&"|"&O35&"|"&P35&"|"&Q35&"|"&R35&"|"&S35&"|"&T35&"|"&U35&"|"&V35&"|"&W35&"|"&X35 | AC35: =IF(COUNTIF($AB$2:AB35,AB35)>1,1,0) | AD35: =STDEV(F35:X35) | AE35: =IF(OR(AA35>=8,AC35=1,AD35=0),0,1) | AF35: =IF(AE35=1,"",IF(AC35=1,"Trùng",IF(AA35>=8,"Bỏ trống "&AA35&" ô","Chọn cùng một mức"))) | AG35: =IF($AE35=1,AVERAGE(F35:I35),"") | AH35: =IF($AE35=1,AVERAGE(J35:M35),"") | AI35: =IF($AE35=1,AVERAGE(N35:Q35),"") | AJ35: =IF($AE35=1,AVERAGE(R35:U35),"") | AK35: =IF($AE35=1,AVERAGE(V35:X35),"")
A36: 45722.222 | B36: 2 | C36: 3 | D36: 1 | E36: 3 | F36: 4 | G36: 3 | H36: 5 | I36: 4 | J36: 3 | K36: 3 | L36: 4 | M36: 3 | N36: 3 | O36: 4 | P36: 2 | Q36: 3 | R36: 4 | S36: 5 | T36: 5 | U36: 4 | V36: 3 | W36: 3 | X36: 4 | Y36: =INT(A36) | Z36: =IF(Y36<DATE(2025,3,6),1,IF(Y36<DATE(2025,3,13),2,3)) | AA36: =COUNTBLANK(B36:X36) | AB36: =B36&"|"&C36&"|"&D36&"|"&E36&"|"&F36&"|"&G36&"|"&H36&"|"&I36&"|"&J36&"|"&K36&"|"&L36&"|"&M36&"|"&N36&"|"&O36&"|"&P36&"|"&Q36&"|"&R36&"|"&S36&"|"&T36&"|"&U36&"|"&V36&"|"&W36&"|"&X36 | AC36: =IF(COUNTIF($AB$2:AB36,AB36)>1,1,0) | AD36: =STDEV(F36:X36) | AE36: =IF(OR(AA36>=8,AC36=1,AD36=0),0,1) | AF36: =IF(AE36=1,"",IF(AC36=1,"Trùng",IF(AA36>=8,"Bỏ trống "&AA36&" ô","Chọn cùng một mức"))) | AG36: =IF($AE36=1,AVERAGE(F36:I36),"") | AH36: =IF($AE36=1,AVERAGE(J36:M36),"") | AI36: =IF($AE36=1,AVERAGE(N36:Q36),"") | AJ36: =IF($AE36=1,AVERAGE(R36:U36),"") | AK36: =IF($AE36=1,AVERAGE(V36:X36),"")
A37: 45722.267 | B37: 1 | C37: 1 | D37: 1 | E37: 2 | F37: 4 | G37: 4 | H37: 4 | I37: 3 | J37: 3 | K37: 3 | L37: 4 | M37: 4 | N37: 4 | O37: 4 | P37: 3 | Q37: 4 | R37: 3 | S37: 3 | T37: 2 | U37: 3 | V37: 3 | W37: 4 | X37: 4 | Y37: =INT(A37) | Z37: =IF(Y37<DATE(2025,3,6),1,IF(Y37<DATE(2025,3,13),2,3)) | AA37: =COUNTBLANK(B37:X37) | AB37: =B37&"|"&C37&"|"&D37&"|"&E37&"|"&F37&"|"&G37&"|"&H37&"|"&I37&"|"&J37&"|"&K37&"|"&L37&"|"&M37&"|"&N37&"|"&O37&"|"&P37&"|"&Q37&"|"&R37&"|"&S37&"|"&T37&"|"&U37&"|"&V37&"|"&W37&"|"&X37 | AC37: =IF(COUNTIF($AB$2:AB37,AB37)>1,1,0) | AD37: =STDEV(F37:X37) | AE37: =IF(OR(AA37>=8,AC37=1,AD37=0),0,1) | AF37: =IF(AE37=1,"",IF(AC37=1,"Trùng",IF(AA37>=8,"Bỏ trống "&AA37&" ô","Chọn cùng một mức"))) | AG37: =IF($AE37=1,AVERAGE(F37:I37),"") | AH37: =IF($AE37=1,AVERAGE(J37:M37),"") | AI37: =IF($AE37=1,AVERAGE(N37:Q37),"") | AJ37: =IF($AE37=1,AVERAGE(R37:U37),"") | AK37: =IF($AE37=1,AVERAGE(V37:X37),"")
A38: 45722.361 | B38: 2 | C38: 3 | D38: 3 | E38: 3 | F38: 4 | G38: 4 | H38: 5 | I38: 4 | J38: 3 | K38: 3 | L38: 3 | M38: 3 | N38: 3 | O38: 2 | P38: 2 | Q38: 3 | R38: 2 | S38: 2 | T38: 3 | U38: 1 | V38: 3 | W38: 3 | X38: 3 | Y38: =INT(A38) | Z38: =IF(Y38<DATE(2025,3,6),1,IF(Y38<DATE(2025,3,13),2,3)) | AA38: =COUNTBLANK(B38:X38) | AB38: =B38&"|"&C38&"|"&D38&"|"&E38&"|"&F38&"|"&G38&"|"&H38&"|"&I38&"|"&J38&"|"&K38&"|"&L38&"|"&M38&"|"&N38&"|"&O38&"|"&P38&"|"&Q38&"|"&R38&"|"&S38&"|"&T38&"|"&U38&"|"&V38&"|"&W38&"|"&X38 | AC38: =IF(COUNTIF($AB$2:AB38,AB38)>1,1,0) | AD38: =STDEV(F38:X38) | AE38: =IF(OR(AA38>=8,AC38=1,AD38=0),0,1) | AF38: =IF(AE38=1,"",IF(AC38=1,"Trùng",IF(AA38>=8,"Bỏ trống "&AA38&" ô","Chọn cùng một mức"))) | AG38: =IF($AE38=1,AVERAGE(F38:I38),"") | AH38: =IF($AE38=1,AVERAGE(J38:M38),"") | AI38: =IF($AE38=1,AVERAGE(N38:Q38),"") | AJ38: =IF($AE38=1,AVERAGE(R38:U38),"") | AK38: =IF($AE38=1,AVERAGE(V38:X38),"")
A39: 45722.365 | B39: 1 | C39: 1 | D39: 1 | E39: 2 | F39: 5 | G39: 4 | H39: 5 | I39: 3 | J39: 3 | K39: 3 | L39: 4 | M39: 4 | N39: 2 | O39: 3 | P39: 2 | Q39: 2 | R39: 3 | S39: 3 | T39: 3 | U39: 3 | V39: 3 | W39: 4 | X39: 4 | Y39: =INT(A39) | Z39: =IF(Y39<DATE(2025,3,6),1,IF(Y39<DATE(2025,3,13),2,3)) | AA39: =COUNTBLANK(B39:X39) | AB39: =B39&"|"&C39&"|"&D39&"|"&E39&"|"&F39&"|"&G39&"|"&H39&"|"&I39&"|"&J39&"|"&K39&"|"&L39&"|"&M39&"|"&N39&"|"&O39&"|"&P39&"|"&Q39&"|"&R39&"|"&S39&"|"&T39&"|"&U39&"|"&V39&"|"&W39&"|"&X39 | AC39: =IF(COUNTIF($AB$2:AB39,AB39)>1,1,0) | AD39: =STDEV(F39:X39) | AE39: =IF(OR(AA39>=8,AC39=1,AD39=0),0,1) | AF39: =IF(AE39=1,"",IF(AC39=1,"Trùng",IF(AA39>=8,"Bỏ trống "&AA39&" ô","Chọn cùng một mức"))) | AG39: =IF($AE39=1,AVERAGE(F39:I39),"") | AH39: =IF($AE39=1,AVERAGE(J39:M39),"") | AI39: =IF($AE39=1,AVERAGE(N39:Q39),"") | AJ39: =IF($AE39=1,AVERAGE(R39:U39),"") | AK39: =IF($AE39=1,AVERAGE(V39:X39),"")
A40: 45722.366 | B40: 1 | C40: 1 | D40: 1 | E40: 2 | F40: 5 | G40: 4 | H40: 5 | I40: 3 | J40: 3 | K40: 3 | L40: 4 | M40: 4 | N40: 2 | O40: 3 | P40: 2 | Q40: 2 | R40: 3 | S40: 3 | T40: 3 | U40: 3 | V40: 3 | W40: 4 | X40: 4 | Y40: =INT(A40) | Z40: =IF(Y40<DATE(2025,3,6),1,IF(Y40<DATE(2025,3,13),2,3)) | AA40: =COUNTBLANK(B40:X40) | AB40: =B40&"|"&C40&"|"&D40&"|"&E40&"|"&F40&"|"&G40&"|"&H40&"|"&I40&"|"&J40&"|"&K40&"|"&L40&"|"&M40&"|"&N40&"|"&O40&"|"&P40&"|"&Q40&"|"&R40&"|"&S40&"|"&T40&"|"&U40&"|"&V40&"|"&W40&"|"&X40 | AC40: =IF(COUNTIF($AB$2:AB40,AB40)>1,1,0) | AD40: =STDEV(F40:X40) | AE40: =IF(OR(AA40>=8,AC40=1,AD40=0),0,1) | AF40: =IF(AE40=1,"",IF(AC40=1,"Trùng",IF(AA40>=8,"Bỏ trống "&AA40&" ô","Chọn cùng một mức"))) | AG40: =IF($AE40=1,AVERAGE(F40:I40),"") | AH40: =IF($AE40=1,AVERAGE(J40:M40),"") | AI40: =IF($AE40=1,AVERAGE(N40:Q40),"") | AJ40: =IF($AE40=1,AVERAGE(R40:U40),"") | AK40: =IF($AE40=1,AVERAGE(V40:X40),"")
A41: 45722.491 | B41: 2 | C41: 1 | D41: 2 | E41: 1 | F41: 4 | G41: 5 | H41: 4 | I41: 4 | J41: 2 | K41: 2 | L41: 3 | M41: 2 | N41: 4 | O41: 4 | P41: 4 | Q41: 4 | R41: 3 | S41: 2 | T41: 3 | U41: 2 | V41: 3 | W41: 4 | X41: 3 | Y41: =INT(A41) | Z41: =IF(Y41<DATE(2025,3,6),1,IF(Y41<DATE(2025,3,13),2,3)) | AA41: =COUNTBLANK(B41:X41) | AB41: =B41&"|"&C41&"|"&D41&"|"&E41&"|"&F41&"|"&G41&"|"&H41&"|"&I41&"|"&J41&"|"&K41&"|"&L41&"|"&M41&"|"&N41&"|"&O41&"|"&P41&"|"&Q41&"|"&R41&"|"&S41&"|"&T41&"|"&U41&"|"&V41&"|"&W41&"|"&X41 | AC41: =IF(COUNTIF($AB$2:AB41,AB41)>1,1,0) | AD41: =STDEV(F41:X41) | AE41: =IF(OR(AA41>=8,AC41=1,AD41=0),0,1) | AF41: =IF(AE41=1,"",IF(AC41=1,"Trùng",IF(AA41>=8,"Bỏ trống "&AA41&" ô","Chọn cùng một mức"))) | AG41: =IF($AE41=1,AVERAGE(F41:I41),"") | AH41: =IF($AE41=1,AVERAGE(J41:M41),"") | AI41: =IF($AE41=1,AVERAGE(N41:Q41),"") | AJ41: =IF($AE41=1,AVERAGE(R41:U41),"") | AK41: =IF($AE41=1,AVERAGE(V41:X41),"")
...

Sheet 7_NhatKyThuThap
A1: NHẬT KÝ THU THẬP TỪNG NGÀY (Bảng BS10 của sách)
A2: Cột B đến D: số người được mời trong ngày theo kênh (sinh viên tự ghi). Cột F, G: đếm tự động từ sheet 6 bằng COUNTIFS. Google Form không biết phiếu đến từ kênh nào nên nhật ký chỉ đếm tổng số phiếu nhận theo ngày.
A3: Ngày | B3: Email | C3: Zalo | D3: Quầy | E3: Mời trong ngày | F3: Phiếu nhận | G3: Phiếu lỗi | H3: Mời lũy kế | I3: Nhận lũy kế | J3: Hợp lệ lũy kế | K3: Vấn đề và cách xử lý
A4: 45719 | B4: 50 | C4: 0 | D4: 5 | E4: =SUM(B4:D4) | F4: =COUNTIF('6_DuLieuThoGanCo'!$Y$2:$Y$166,A4) | G4: =COUNTIFS('6_DuLieuThoGanCo'!$Y$2:$Y$166,A4,'6_DuLieuThoGanCo'!$AE$2:$AE$166,0) | H4: =SUM($E$4:E4) | I4: =SUM($F$4:F4) | J4: =SUM($F$4:F4)-SUM($G$4:G4) | K4: Gửi 50 email; mời tại quầy 8 giờ đến 10 giờ
A5: 45720 | B5: 0 | C5: 40 | D5: 8 | E5: =SUM(B5:D5) | F5: =COUNTIF('6_DuLieuThoGanCo'!$Y$2:$Y$166,A5) | G5: =COUNTIFS('6_DuLieuThoGanCo'!$Y$2:$Y$166,A5,'6_DuLieuThoGanCo'!$AE$2:$AE$166,0) | H5: =SUM($E$4:E5) | I5: =SUM($F$4:F5) | J5: =SUM($F$4:F5)-SUM($G$4:G5) | K5: Gửi Zalo cho 40 khách hàng
A6: 45721 | B6: 0 | C6: 30 | D6: 0 | E6: =SUM(B6:D6) | F6: =COUNTIF('6_DuLieuThoGanCo'!$Y$2:$Y$166,A6) | G6: =COUNTIFS('6_DuLieuThoGanCo'!$Y$2:$Y$166,A6,'6_DuLieuThoGanCo'!$AE$2:$AE$166,0) | H6: =SUM($E$4:E6) | I6: =SUM($F$4:F6) | J6: =SUM($F$4:F6)-SUM($G$4:G6) | K6: Gửi Zalo cho 30 khách hàng; quầy không bố trí được chỗ
A7: 45722 | B7: 0 | C7: 0 | D7: 12 | E7: =SUM(B7:D7) | F7: =COUNTIF('6_DuLieuThoGanCo'!$Y$2:$Y$166,A7) | G7: =COUNTIFS('6_DuLieuThoGanCo'!$Y$2:$Y$166,A7,'6_DuLieuThoGanCo'!$AE$2:$AE$166,0) | H7: =SUM($E$4:E7) | I7: =SUM($F$4:F7) | J7: =SUM($F$4:F7)-SUM($G$4:G7) | K7: Nhắc lần 1; ngày nhận nhiều nhất
A8: 45723 | B8: 0 | C8: 0 | D8: 0 | E8: =SUM(B8:D8) | F8: =COUNTIF('6_DuLieuThoGanCo'!$Y$2:$Y$166,A8) | G8: =COUNTIFS('6_DuLieuThoGanCo'!$Y$2:$Y$166,A8,'6_DuLieuThoGanCo'!$AE$2:$AE$166,0) | H8: =SUM($E$4:E8) | I8: =SUM($F$4:F8) | J8: =SUM($F$4:F8)-SUM($G$4:G8) | K8: 2 khách hỏi có phải ngân hàng thu thông tin không: giải thích sinh viên độc lập, không hỏi số tài khoản
A9: 45724 | B9: 0 | C9: 0 | D9: 8 | E9: =SUM(B9:D9) | F9: =COUNTIF('6_DuLieuThoGanCo'!$Y$2:$Y$166,A9) | G9: =COUNTIFS('6_DuLieuThoGanCo'!$Y$2:$Y$166,A9,'6_DuLieuThoGanCo'!$AE$2:$AE$166,0) | H9: =SUM($E$4:E9) | I9: =SUM($F$4:F9) | J9: =SUM($F$4:F9)-SUM($G$4:G9) | K9: Thứ Bảy, quầy mở buổi sáng
A10: 45725 | B10: 0 | C10: 0 | D10: 0 | E10: =SUM(B10:D10) | F10: =COUNTIF('6_DuLieuThoGanCo'!$Y$2:$Y$166,A10) | G10: =COUNTIFS('6_DuLieuThoGanCo'!$Y$2:$Y$166,A10,'6_DuLieuThoGanCo'!$AE$2:$AE$166,0) | H10: =SUM($E$4:E10) | I10: =SUM($F$4:F10) | J10: =SUM($F$4:F10)-SUM($G$4:G10) | K10: Chủ nhật, quầy nghỉ; chỉ nhận phiếu trực tuyến
A11: 45726 | B11: 0 | C11: 0 | D11: 10 | E11: =SUM(B11:D11) | F11: =COUNTIF('6_DuLieuThoGanCo'!$Y$2:$Y$166,A11) | G11: =COUNTIFS('6_DuLieuThoGanCo'!$Y$2:$Y$166,A11,'6_DuLieuThoGanCo'!$AE$2:$AE$166,0) | H11: =SUM($E$4:E11) | I11: =SUM($F$4:F11) | J11: =SUM($F$4:F11)-SUM($G$4:G11) | K11: Đầu ngày kiểm tra tiến độ: 75 phiếu sau 7 ngày; giữ lịch nhắc lần 2 ngày 13/3
A12: 45727 | B12: 0 | C12: 0 | D12: 0 | E12: =SUM(B12:D12) | F12: =COUNTIF('6_DuLieuThoGanCo'!$Y$2:$Y$166,A12) | G12: =COUNTIFS('6_DuLieuThoGanCo'!$Y$2:$Y$166,A12,'6_DuLieuThoGanCo'!$AE$2:$AE$166,0) | H12: =SUM($E$4:E12) | I12: =SUM($F$4:F12) | J12: =SUM($F$4:F12)-SUM($G$4:G12)
A13: 45728 | B13: 0 | C13: 0 | D13: 8 | E13: =SUM(B13:D13) | F13: =COUNTIF('6_DuLieuThoGanCo'!$Y$2:$Y$166,A13) | G13: =COUNTIFS('6_DuLieuThoGanCo'!$Y$2:$Y$166,A13,'6_DuLieuThoGanCo'!$AE$2:$AE$166,0) | H13: =SUM($E$4:E13) | I13: =SUM($F$4:F13) | J13: =SUM($F$4:F13)-SUM($G$4:G13) | K13: Phát hiện 1 phiếu gửi hai lần cách nhau 2 phút; không xóa, để lọc ở mục 3.5.2
A14: 45729 | B14: 0 | C14: 0 | D14: 10 | E14: =SUM(B14:D14) | F14: =COUNTIF('6_DuLieuThoGanCo'!$Y$2:$Y$166,A14) | G14: =COUNTIFS('6_DuLieuThoGanCo'!$Y$2:$Y$166,A14,'6_DuLieuThoGanCo'!$AE$2:$AE$166,0) | H14: =SUM($E$4:E14) | I14: =SUM($F$4:F14) | J14: =SUM($F$4:F14)-SUM($G$4:G14) | K14: Nhắc lần 2; báo ngày đóng 17/3
A15: 45730 | B15: 0 | C15: 0 | D15: 9 | E15: =SUM(B15:D15) | F15: =COUNTIF('6_DuLieuThoGanCo'!$Y$2:$Y$166,A15) | G15: =COUNTIFS('6_DuLieuThoGanCo'!$Y$2:$Y$166,A15,'6_DuLieuThoGanCo'!$AE$2:$AE$166,0) | H15: =SUM($E$4:E15) | I15: =SUM($F$4:F15) | J15: =SUM($F$4:F15)-SUM($G$4:G15)
A16: 45731 | B16: 0 | C16: 0 | D16: 10 | E16: =SUM(B16:D16) | F16: =COUNTIF('6_DuLieuThoGanCo'!$Y$2:$Y$166,A16) | G16: =COUNTIFS('6_DuLieuThoGanCo'!$Y$2:$Y$166,A16,'6_DuLieuThoGanCo'!$AE$2:$AE$166,0) | H16: =SUM($E$4:E16) | I16: =SUM($F$4:F16) | J16: =SUM($F$4:F16)-SUM($G$4:G16)
A17: 45732 | B17: 0 | C17: 0 | D17: 0 | E17: =SUM(B17:D17) | F17: =COUNTIF('6_DuLieuThoGanCo'!$Y$2:$Y$166,A17) | G17: =COUNTIFS('6_DuLieuThoGanCo'!$Y$2:$Y$166,A17,'6_DuLieuThoGanCo'!$AE$2:$AE$166,0) | H17: =SUM($E$4:E17) | I17: =SUM($F$4:F17) | J17: =SUM($F$4:F17)-SUM($G$4:G17)
A18: 45733 | B18: 0 | C18: 0 | D18: 0 | E18: =SUM(B18:D18) | F18: =COUNTIF('6_DuLieuThoGanCo'!$Y$2:$Y$166,A18) | G18: =COUNTIFS('6_DuLieuThoGanCo'!$Y$2:$Y$166,A18,'6_DuLieuThoGanCo'!$AE$2:$AE$166,0) | H18: =SUM($E$4:E18) | I18: =SUM($F$4:F18) | J18: =SUM($F$4:F18)-SUM($G$4:G18) | K18: Đóng khảo sát 10 giờ; tải file thô
A20: Tổng hợp cho mục 3.5.1 | B20: Kết quả
A21: Tổng số người được mời | B21: =SUM(E4:E18)
A22: Tổng phiếu thu về | B22: =SUM(F4:F18)
A23: Tỷ lệ phản hồi | B23: =B22/B21
A24: Phiếu bị loại | B24: =SUM(G4:G18)
A25: Phiếu hợp lệ | B25: =B22-B24
A26: Số ngày thu | B26: =COUNT(A4:A18)

Sheet 8_SomMuon
A1: KIỂM TRA SAI LỆCH DO KHÔNG PHẢN HỒI: NHÓM SỚM VÀ NHÓM MUỘN (Bảng BS13 của sách)
A2: Armstrong và Overton (1977): người trả lời muộn thường giống người không trả lời hơn. Nếu nhóm trả lời sau lần nhắc cuối không khác nhóm trả lời trước lần nhắc đầu thì chưa có dấu hiệu sai lệch do không phản hồi. Nhóm sớm: đợt 1 (3/3 đến 5/3, trước nhắc lần 1). Nhóm muộn: đợt 3 (13/3 đến 17/3, sau nhắc lần 2). Chỉ tính phiếu hợp lệ. T.TEST loại 3: kiểm định t hai mẫu độc lập không giả định phương sai bằng nhau.
A3: Biến | B3: Nhóm sớm | C3: Nhóm muộn | D3: Chênh lệch | E3: P-value | F3: Kết luận
A4: Số phiếu hợp lệ | B4: =COUNTIFS('6_DuLieuThoGanCo'!$Z$2:$Z$166,1,'6_DuLieuThoGanCo'!$AE$2:$AE$166,1) | C4: =COUNTIFS('6_DuLieuThoGanCo'!$Z$2:$Z$166,3,'6_DuLieuThoGanCo'!$AE$2:$AE$166,1) | F4: Đợt 2 có phần còn lại
A5: Sự hữu ích (HI) | B5: =AVERAGE('6_DuLieuThoGanCo'!$AG$2:$AG$31) | C5: =AVERAGE('6_DuLieuThoGanCo'!$AG$109:$AG$166) | D5: =C5-B5 | E5: =_xlfn.T.TEST('6_DuLieuThoGanCo'!$AG$2:$AG$31,'6_DuLieuThoGanCo'!$AG$109:$AG$166,2,3) | F5: =IF(E5<0.05,"Khác biệt: ghi vào hạn chế",IF(E5<0.1,"Gần ngưỡng: nêu thận trọng","Không khác biệt"))
A6: Sự dễ sử dụng (SD) | B6: =AVERAGE('6_DuLieuThoGanCo'!$AH$2:$AH$31) | C6: =AVERAGE('6_DuLieuThoGanCo'!$AH$109:$AH$166) | D6: =C6-B6 | E6: =_xlfn.T.TEST('6_DuLieuThoGanCo'!$AH$2:$AH$31,'6_DuLieuThoGanCo'!$AH$109:$AH$166,2,3) | F6: =IF(E6<0.05,"Khác biệt: ghi vào hạn chế",IF(E6<0.1,"Gần ngưỡng: nêu thận trọng","Không khác biệt"))
A7: Niềm tin (NT) | B7: =AVERAGE('6_DuLieuThoGanCo'!$AI$2:$AI$31) | C7: =AVERAGE('6_DuLieuThoGanCo'!$AI$109:$AI$166) | D7: =C7-B7 | E7: =_xlfn.T.TEST('6_DuLieuThoGanCo'!$AI$2:$AI$31,'6_DuLieuThoGanCo'!$AI$109:$AI$166,2,3) | F7: =IF(E7<0.05,"Khác biệt: ghi vào hạn chế",IF(E7<0.1,"Gần ngưỡng: nêu thận trọng","Không khác biệt"))
A8: Ảnh hưởng xã hội (XH) | B8: =AVERAGE('6_DuLieuThoGanCo'!$AJ$2:$AJ$31) | C8: =AVERAGE('6_DuLieuThoGanCo'!$AJ$109:$AJ$166) | D8: =C8-B8 | E8: =_xlfn.T.TEST('6_DuLieuThoGanCo'!$AJ$2:$AJ$31,'6_DuLieuThoGanCo'!$AJ$109:$AJ$166,2,3) | F8: =IF(E8<0.05,"Khác biệt: ghi vào hạn chế",IF(E8<0.1,"Gần ngưỡng: nêu thận trọng","Không khác biệt"))
A9: Ý định sử dụng (YD) | B9: =AVERAGE('6_DuLieuThoGanCo'!$AK$2:$AK$31) | C9: =AVERAGE('6_DuLieuThoGanCo'!$AK$109:$AK$166) | D9: =C9-B9 | E9: =_xlfn.T.TEST('6_DuLieuThoGanCo'!$AK$2:$AK$31,'6_DuLieuThoGanCo'!$AK$109:$AK$166,2,3) | F9: =IF(E9<0.05,"Khác biệt: ghi vào hạn chế",IF(E9<0.1,"Gần ngưỡng: nêu thận trọng","Không khác biệt"))
A11: Cách đọc: cả năm P-value đều lớn hơn 0,05 nên chưa có dấu hiệu sai lệch do không phản hồi. Niềm tin có P-value gần 0,1 và nhóm muộn đánh giá thấp hơn: khóa luận nên nêu điều này một cách thận trọng ở mục hạn chế, vì người không trả lời có thể tin ngân hàng số ít hơn.

Sheet 9_SaiLechPPChung
A1: TRẢ LỜI CẨU THẢ VÀ SAI LỆCH PHƯƠNG PHÁP CHUNG (Bảng BS12 của sách)
A2: Kiểm tra | B2: Kết quả | C2: Cách đọc
A3: Phiếu chọn cùng một mức cho mọi câu (độ lệch chuẩn dòng = 0) | B3: =COUNTIF('6_DuLieuThoGanCo'!$AD$2:$AD$166,0) | C3: Bằng 0: không có phiếu trả lời theo một đường thẳng
